Workbook

Sheet Var.
B2: # | C2: Mapas | D2: Variable | E2: OBS
B3: 1 | C3: Population Censo - 1991 | D3: POP_91
B4: 2 | C4: % Extremely poor - 1991 | D4: PIND_91
B5: 3 | C5: % Poor - 1991 | D5: PMPOB_91
B6: 4 | C6: Number of extremely poor - 1991 | D6: NEPOB_91
B7: 5 | C7: Number of poor - 1991 | D7: NPOB_91
B8: 6 | C8: Index % Extremely poor BR - 1991 | D8: PIND_br_91 | E8: Brazil Average = 100
B9: 7 | C9: Population Censo - 2000 | D9: POP_00
B10: 8 | C10: % Extremely poor - 2000 | D10: PIND_00
B11: 9 | C11: % Poor - 2000 | D11: PMPOB_00
B12: 10 | C12: Number of extremely poor - 2000 | D12: NEPOB_00
B13: 11 | C13: Number of poor - 2000 | D13: NPOB_00
B14: 12 | C14: Index % Extremely poor BR - 2000 | D14: PIND_br_00 | E14: Brazil Average = 100
B15: 13 | C15: Population Censo - 2010 | D15: POP_10
B16: 14 | C16: % Extremely poor - 2010 | D16: PIND_10
B17: 15 | C17: % Poor - 2010 | D17: PMPOB_10
B18: 16 | C18: Number of extremely poor - 2010 | D18: NEPOB_10
B19: 17 | C19: Number of poor - 2010 | D19: NPOB_10
B20: 18 | C20: Index % Extremely poor BR - 2010 | D20: PIND_br_10 | E20: Brazil Average = 100
B21: 19 | C21: GINI - 1991 | D21: GINI_91
B22: 20 | C22: GINI - 2000 | D22: GINI_00
B23: 21 | C23: GINI - 2010 | D23: GINI_10
B24: 22 | C24: Index GINI BR - 1991 | D24: GINI_br_91 | E24: Brazil Average = 100
B25: 23 | C25: Index GINI BR - 2000 | D25: GINI_br_00 | E25: Brazil Average = 100
B26: 24 | C26: Index GINI BR - 2010 | D26: GINI_br_10 | E26: Brazil Average = 100
B27: 25 | C27: GDP - 1999 | D27: GDP_99
B28: 26 | C28: GDP - 2014 | D28: GDP_14
B29: 27 | C29: GDPpc - 1999 | D29: GDPPC_99
B30: 28 | C30: GDPpc - 2014 | D30: GDPPC_14
B31: 29 | C31: Population - 1999 | D31: POP_99
B32: 30 | C32: Population - 2014 | D32: POP_14
B33: 31 | C33: Index GDPpc BR - 1999 | D33: GDPpc_br_99 | E33: Brazil Average = 100
B34: 32 | C34: Index GDPpc BR - 2014 | D34: GDPpc_br_14 | E34: Brazil Average = 100
B35: 33 | C35: IDHM - 1991 | D35: IDHM_91
B36: 34 | C36: IDHM Education - 1991 | D36: IDHM_E_91
B37: 35 | C37: IDHM Longevity - 1991 | D37: IDHM_L_91
B38: 36 | C38: IDHM Income - 1991 | D38: IDHM_R_91
B39: 37 | C39: IDHM - 2000 | D39: IDHM_00
B40: 38 | C40: IDHM Education - 2000 | D40: IDHM_E_00
B41: 39 | C41: IDHM Longevity - 2000 | D41: IDHM_L_00
...

Sheet Censo Desc.
B3: POP | C3: População total em domicílios particulares permanentes | D3: População total que reside em domicílios particulares permanentes | E3: População residente em domicílios particulares permanentes. Exclui os residentes em domicílios coletivos, como pensões, hotéis, prisões, quartéis, hospitais.
B4: PIND | C4: % de extremamente pobres | D4: Proporção de extremamente pobres | E4: Proporção dos indivíduos com renda domiciliar per capita igual ou inferior a R$ 70,00 mensais, em reais de agosto de 2010. O universo de indivíduos é limitado àqueles que vivem em domicílios particulares permanentes.
B5: PMPOB | C5: % de pobres | D5: Proporção de pobres | E5: Proporção dos indivíduos com renda domiciliar per capita igual ou inferior a R$ 140,00 mensais, em reais de agosto de 2010. O universo de indivíduos é limitado àqueles que vivem em domicílios particulares permanentes.
B6: NEPOB | C6: Número de extremamente pobres | D6: - | E6: -
B7: NPOB | C7: Número de pobres | D7: - | E7: -
B8: GINI | C8: Índice de Gini | D8: GINI | E8: Mede o grau de desigualdade existente na distribuição de indivíduos segundo a renda domiciliar per capita. Seu valor varia de 0, quando não há desigualdade (a renda domiciliar per capita de todos os indivíduos tem o mesmo valor), a 1, quando a desigualdade é máxima (apenas um indivíduo detém toda a renda).O universo de indivíduos é limitado àqueles que vivem em domicílios particulares permanentes.

Sheet Mariana
A1: Código | B1: Região | C1: UF | D1: Município | E1: POP_91 | F1: PIND_91 | G1: PMPOB_91 | H1: NEPOB_91 | I1: NPOB_91 | J1: PIND_br_91 | K1: POP_00 | L1: PIND_00 | M1: PMPOB_00 | N1: NEPOB_00 | O1: NPOB_00 | P1: PIND_br_00 | Q1: POP_10 | R1: PIND_10 | S1: PMPOB_10 | T1: NEPOB_10 | U1: NPOB_10 | V1: PIND_br_10 | W1: GINI_91 | X1: GINI_00 | Y1: GINI_10 | Z1: GINI_br_91 | AA1: GINI_br_00 | AB1: GINI_br_10 | AC1: GDP_99 | AD1: GDP_14 | AE1: GDPPC_99 | AF1: GDPPC_14 | AG1: POP_99 | AH1: POP_14 | AI1: GDPPC_br_99 | AJ1: GDPPC_br_14 | AK1: IDHM_91 | AL1: IDHM_E_91 | AM1: IDHM_L_91 | AN1: IDHM_R_91 | AO1: IDHM_00 | AP1: IDHM_E_00 | AQ1: IDHM_L_00 | AR1: IDHM_R_00 | AS1: IDHM_10 | AT1: IDHM_E_10 | AU1: IDHM_L_10 | AV1: IDHM_R_10 | AW1: VAagr_14 | AX1: VAind_14 | AY1: VAser_14 | AZ1: VAadm_14 | BA1: VAagr_14_S | BB1: VAind_14_S | BC1: VAser_14_S | BD1: VAadm_14_S | BG1: POP_10 | BH1: PIND_10 | BI1: PMPOB_10 | BJ1: NEPOB_10 | BK1: NPOB_10 | BL1: PIND_br_10 | BM1: GINI_91 | BN1: GINI_00 | BO1: GINI_10 | BP1: GINI_br_91 | BQ1: GINI_br_00 | BR1: GINI_br_10 | BS1: GDP_99 | BT1: GDP_14 | BU1: GDPPC_99 | BV1: GDPPC_14 | BW1: POP_99 | BX1: POP_14 | BY1: GDPPC_br_99 | BZ1: GDPPC_br_14 | CA1: IDHM_91 | CB1: IDHM_E_91 | CC1: IDHM_L_91 | CD1: IDHM_R_91 | CE1: IDHM_00 | CF1: IDHM_E_00 | CG1: IDHM_L_00 | CH1: IDHM_R_00 | CI1: IDHM_10 | CJ1: IDHM_E_10 | CK1: IDHM_L_10 | CL1: IDHM_R_10 | CM1: VAagr_14 | CN1: VAind_14 | CO1: VAser_14 | CP1: VAadm_14 | CQ1: VAagr_14_S | CR1: VAind_14_S | CS1: VAser_14_S | CT1: VAadm_14_S | CW1: PIND_10 | CX1: PMPOB_10 | CY1: GINI_10 | CZ1: GDPPC_14 | DA1: POP_14 | DB1: IDHM_10 | DC1: IDHM_E_10 | DD1: IDHM_L_10 | DE1: IDHM_R_10 | DF1: VAagr_14_S | DG1: VAind_14_S | DH1: VAser_14_S | DI1: VAadm_14_S
A2: 314000 | B2: Sudeste | C2: MG | D2: Mariana | E2: 37808 | F2: 20.93 | G2: 45.34 | H2: 7913.2144 | I2: 17142.147 | J2: 67.4697 | K2: 46215 | L2: 11.36 | M2: 31.3 | N2: 5250.024 | O2: 14465.295 | P2: 54.904 | Q2: 53910 | R2: 3.57 | S2: 11.72 | T2: 1924.587 | U2: 6318.252 | V2: 31.4776 | W2: 0.6 | X2: 0.57 | Y2: 0.51 | Z2: 114.1862 | AA2: 104.1936 | AB2: 103.1593 | AC2: 324633.98 | AD2: 5010520.4 | AE2: 7008.2031 | AF2: 86042.63 | AG2: 46322 | AH2: 58233 | AI2: 174.0373 | AJ2: 461.4062 | AK2: 0.493 | AL2: 0.279 | AM2: 0.722 | AN2: 0.596 | AO2: 0.62 | AP2: 0.474 | AQ2: 0.787 | AR2: 0.638 | AS2: 0.742 | AT2: 0.664 | AU2: 0.874 | AV2: 0.705 | AW2: 23107 | AX2: 3427697 | AY2: 1215651 | AZ2: 202290 | BA2: =AW2/SUM($AW2:$AZ2) -> 0.0047459869 | BB2: =AX2/SUM($AW2:$AZ2) -> 0.70402065 | BC2: =AY2/SUM($AW2:$AZ2) -> 0.24968467 | BD2: =AZ2/SUM($AW2:$AZ2) -> 0.041548695 | CW2: =INDEX(Var.!$C$3:$D$54,MATCH(Mariana!CW$1,Var.!$D$3:$D$54,0),1) -> % Extremely poor - 2010 | CX2: =INDEX(Var.!$C$3:$D$54,MATCH(Mariana!CX$1,Var.!$D$3:$D$54,0),1) -> % Poor - 2010 | CY2: =INDEX(Var.!$C$3:$D$54,MATCH(Mariana!CY$1,Var.!$D$3:$D$54,0),1) -> GINI - 2010 | CZ2: =INDEX(Var.!$C$3:$D$54,MATCH(Mariana!CZ$1,Var.!$D$3:$D$54,0),1) -> GDPpc - 2014 | DA2: =INDEX(Var.!$C$3:$D$54,MATCH(Mariana!DA$1,Var.!$D$3:$D$54,0),1) -> Population - 2014 | DB2: =INDEX(Var.!$C$3:$D$54,MATCH(Mariana!DB$1,Var.!$D$3:$D$54,0),1) -> IDHM - 2010 | DC2: =INDEX(Var.!$C$3:$D$54,MATCH(Mariana!DC$1,Var.!$D$3:$D$54,0),1) -> IDHM Education - 2010 | DD2: =INDEX(Var.!$C$3:$D$54,MATCH(Mariana!DD$1,Var.!$D$3:$D$54,0),1) -> IDHM Longevity - 2010 | ... DI2: =INDEX(Var.!$C$3:$D$54,MATCH(Mariana!DI$1,Var.!$D$3:$D$54,0),1) -> #N/A | DJ2: Avg. diference | DL2: Matching - Mariana | DP2: Municipios com atividade da Vale
A4: 310010 | B4: Sudeste | C4: MG | D4: Abadia dos Dourados | E4: 6410 | F4: 11.86 | G4: 40.41 | H4: 760.226 | I4: 2590.281 | J4: 38.2317 | K4: 6348 | L4: 5.48 | M4: 25.41 | N4: 347.8704 | O4: 1613.0268 | P4: 26.4854 | Q4: 6658 | R4: 1.85 | S4: 7.94 | T4: 123.173 | U4: 528.6452 | V4: 16.3119 | W4: 0.46 | X4: 0.5 | Y4: 0.47 | Z4: 87.5428 | AA4: 91.3979 | AB4: 95.0684 | AC4: 21849.784 | AD4: 191575.46 | AE4: 3388.6141 | AF4: 27399.24 | AG4: 6448 | AH4: 6992 | AI4: 84.1507 | AJ4: 146.9292 | AK4: 0.449 | AL4: 0.225 | AM4: 0.728 | AN4: 0.551 | AO4: 0.575 | AP4: 0.387 | AQ4: 0.799 | AR4: 0.616 | AS4: 0.689 | AT4: 0.563 | AU4: 0.839 | AV4: 0.693 | AW4: 40747 | AX4: 50109 | AY4: 64828 | AZ4: 25528 | BA4: =AW4/SUM($AW4:$AZ4) -> 0.22485818 | BB4: =AX4/SUM($AW4:$AZ4) -> 0.27652142 | BC4: =AY4/SUM($AW4:$AZ4) -> 0.35774673 | BD4: =AZ4/SUM($AW4:$AZ4) -> 0.14087367 | BG4: =(Q4/Q$2-1)^2 -> 0.76824851 | BH4: =(R4/R$2-1)^2 -> 0.23212422 | BI4: =(S4/S$2-1)^2 -> 0.10402276 | BJ4: =(T4/T$2-1)^2 -> 0.87609655 | BK4: =(U4/U$2-1)^2 -> 0.83966152 | BL4: =(V4/V$2-1)^2 -> 0.23212488 | BM4: =(W4/W$2-1)^2 -> 0.054444444 | BN4: =(X4/X$2-1)^2 -> 0.015081564 | ... CT4: =(BD4/BD$2-1)^2 -> 5.7148151 | CV4: =D4 -> Abadia dos Dourados | CW4: =INDEX($BG$4:$CT$855,MATCH($CV4,$D$4:$D$855,0),MATCH(CW$1,$BG$1:$CT$1,0)) -> 0.23212422 | CX4: =INDEX($BG$4:$CT$855,MATCH($CV4,$D$4:$D$855,0),MATCH(CX$1,$BG$1:$CT$1,0)) -> 0.10402276 | CY4: =INDEX($BG$4:$CT$855,MATCH($CV4,$D$4:$D$855,0),MATCH(CY$1,$BG$1:$CT$1,0)) -> 0.0061514802 | CZ4: =INDEX($BG$4:$CT$855,MATCH($CV4,$D$4:$D$855,0),MATCH(CZ$1,$BG$1:$CT$1,0)) -> 0.46452681 | DA4: =INDEX($BG$4:$CT$855,MATCH($CV4,$D$4:$D$855,0),MATCH(DA$1,$BG$1:$CT$1,0)) -> 0.7742779 | DB4: =INDEX($BG$4:$CT$855,MATCH($CV4,$D$4:$D$855,0),MATCH(DB$1,$BG$1:$CT$1,0)) -> 0.0051020408 | DC4: =INDEX($BG$4:$CT$855,MATCH($CV4,$D$4:$D$855,0),MATCH(DC$1,$BG$1:$CT$1,0)) -> 0.023136976 | DD4: =INDEX($BG$4:$CT$855,MATCH($CV4,$D$4:$D$855,0),MATCH(DD$1,$BG$1:$CT$1,0)) -> 0.0016036634 | ... DI4: =INDEX($BG$4:$CT$855,MATCH($CV4,$D$4:$D$855,0),MATCH(DI$1,$BG$1:$CT$1,0)) -> 5.7148151 | DJ4: =AVERAGE(CW4:DI4) -> 166.06584 | DL4: 1 | DM4: =SMALL($DJ$4:$DJ$855,DL4) -> 0.040871664 | DN4: =INDEX($CV$4:$DJ$855,MATCH($DM4,$DJ$4:$DJ$855,0),1) -> Ouro Preto | DP4: Barão de Cocais | DQ4: =INDEX($DL$4:$DN$855,MATCH($DP4,$DN$4:$DN$855,0),1) -> 20
A5: 310020 | B5: Sudeste | C5: MG | D5: Abaeté | E5: 20273 | F5: 13.43 | G5: 47.17 | H5: 2722.6639 | I5: 9562.7741 | J5: 43.2928 | K5: 22150 | L5: 3.1 | M5: 19.13 | N5: 686.65 | O5: 4237.295 | P5: 14.9826 | Q5: 22456 | R5: 1.61 | S5: 6.69 | T5: 361.5416 | U5: 1502.3064 | V5: 14.1958 | W5: 0.52 | X5: 0.58 | Y5: 0.54 | Z5: 98.9614 | AA5: 106.0216 | AB5: 109.2275 | AC5: 85663.344 | AD5: 350411.46 | AE5: 3844.1637 | AF5: 14914.93 | AG5: 22284 | AH5: 23494 | AI5: 95.4635 | AJ5: 79.9818 | AK5: 0.417 | AL5: 0.18 | AM5: 0.717 | AN5: 0.561 | AO5: 0.587 | AP5: 0.385 | AQ5: 0.792 | AR5: 0.664 | AS5: 0.698 | AT5: 0.556 | AU5: 0.848 | AV5: 0.72 | AW5: 49998 | AX5: 42433 | AY5: 159247 | AZ5: 71575 | BA5: =AW5/SUM($AW5:$AZ5) -> 0.15467142 | BB5: =AX5/SUM($AW5:$AZ5) -> 0.1312687 | BC5: =AY5/SUM($AW5:$AZ5) -> 0.49263889 | BD5: =AZ5/SUM($AW5:$AZ5) -> 0.22142099 | BG5: =(Q5/Q$2-1)^2 -> 0.34041846 | BH5: =(R5/R$2-1)^2 -> 0.30142253 | BI5: =(S5/S$2-1)^2 -> 0.18419623 | BJ5: =(T5/T$2-1)^2 -> 0.65958093 | BK5: =(U5/U$2-1)^2 -> 0.5809908 | BL5: =(V5/V$2-1)^2 -> 0.30142185 | BM5: =(W5/W$2-1)^2 -> 0.017777778 | BN5: =(X5/X$2-1)^2 -> 0.00030778701 | ... CT5: =(BD5/BD$2-1)^2 -> 18.741908 | CV5: =D5 -> Abaeté | CW5: =INDEX($BG$4:$CT$855,MATCH($CV5,$D$4:$D$855,0),MATCH(CW$1,$BG$1:$CT$1,0)) -> 0.30142253 | CX5: =INDEX($BG$4:$CT$855,MATCH($CV5,$D$4:$D$855,0),MATCH(CX$1,$BG$1:$CT$1,0)) -> 0.18419623 | CY5: =INDEX($BG$4:$CT$855,MATCH($CV5,$D$4:$D$855,0),MATCH(CY$1,$BG$1:$CT$1,0)) -> 0.0034602076 | CZ5: =INDEX($BG$4:$CT$855,MATCH($CV5,$D$4:$D$855,0),MATCH(CZ$1,$BG$1:$CT$1,0)) -> 0.68336098 | DA5: =INDEX($BG$4:$CT$855,MATCH($CV5,$D$4:$D$855,0),MATCH(DA$1,$BG$1:$CT$1,0)) -> 0.35587403 | DB5: =INDEX($BG$4:$CT$855,MATCH($CV5,$D$4:$D$855,0),MATCH(DB$1,$BG$1:$CT$1,0)) -> 0.0035163941 | DC5: =INDEX($BG$4:$CT$855,MATCH($CV5,$D$4:$D$855,0),MATCH(DC$1,$BG$1:$CT$1,0)) -> 0.026455218 | DD5: =INDEX($BG$4:$CT$855,MATCH($CV5,$D$4:$D$855,0),MATCH(DD$1,$BG$1:$CT$1,0)) -> 0.00088496039 | ... DI5: =INDEX($BG$4:$CT$855,MATCH($CV5,$D$4:$D$855,0),MATCH(DI$1,$BG$1:$CT$1,0)) -> 18.741908 | DJ5: =AVERAGE(CW5:DI5) -> 78.448798 | DL5: =DL4+1 -> 2 | DM5: =SMALL($DJ$4:$DJ$855,DL5) -> 0.11939873 | DN5: =INDEX($CV$4:$DJ$855,MATCH($DM5,$DJ$4:$DJ$855,0),1) -> Ouro Branco | DP5: Belo Vale | DQ5: =INDEX($DL$4:$DN$855,MATCH($DP5,$DN$4:$DN$855,0),1) -> 459
A6: 310030 | B6: Sudeste | C6: MG | D6: Abre Campo | E6: 13072 | F6: 34.35 | G6: 68.81 | H6: 4490.232 | I6: 8994.8432 | J6: 110.7302 | K6: 13127 | L6: 15.38 | M6: 35.35 | N6: 2018.9326 | O6: 4640.3945 | P6: 74.3331 | Q6: 13114 | R6: 8.17 | S6: 23.33 | T6: 1071.4138 | U6: 3059.4962 | V6: 72.0369 | W6: 0.52 | X6: 0.51 | Y6: 0.52 | Z6: 98.9614 | AA6: 93.2259 | AB6: 105.182 | AC6: 55015.041 | AD6: 155372.11 | AE6: 4120.9769 | AF6: 11331.93 | AG6: 13350 | AH6: 13711 | AI6: 102.3377 | AJ6: 60.7678 | AK6: 0.379 | AL6: 0.168 | AM6: 0.678 | AN6: 0.479 | AO6: 0.54 | AP6: 0.36 | AQ6: 0.746 | AR6: 0.586 | AS6: 0.654 | AT6: 0.525 | AU6: 0.823 | AV6: 0.646 | AW6: 27329 | AX6: 8438 | AY6: 66583 | AZ6: 42739 | BA6: =AW6/SUM($AW6:$AZ6) -> 0.18836025 | BB6: =AX6/SUM($AW6:$AZ6) -> 0.058157407 | BC6: =AY6/SUM($AW6:$AZ6) -> 0.45891143 | BD6: =AZ6/SUM($AW6:$AZ6) -> 0.29457092 | BG6: =(Q6/Q$2-1)^2 -> 0.57265954 | BH6: =(R6/R$2-1)^2 -> 1.660272 | BI6: =(S6/S$2-1)^2 -> 0.98131676 | BJ6: =(T6/T$2-1)^2 -> 0.19651663 | BK6: =(U6/U$2-1)^2 -> 0.26601722 | BL6: =(V6/V$2-1)^2 -> 1.660266 | BM6: =(W6/W$2-1)^2 -> 0.017777778 | BN6: =(X6/X$2-1)^2 -> 0.011080332 | ... CT6: =(BD6/BD$2-1)^2 -> 37.085366 | CV6: =D6 -> Abre Campo | CW6: =INDEX($BG$4:$CT$855,MATCH($CV6,$D$4:$D$855,0),MATCH(CW$1,$BG$1:$CT$1,0)) -> 1.660272 | CX6: =INDEX($BG$4:$CT$855,MATCH($CV6,$D$4:$D$855,0),MATCH(CX$1,$BG$1:$CT$1,0)) -> 0.98131676 | CY6: =INDEX($BG$4:$CT$855,MATCH($CV6,$D$4:$D$855,0),MATCH(CY$1,$BG$1:$CT$1,0)) -> 0.00038446751 | CZ6: =INDEX($BG$4:$CT$855,MATCH($CV6,$D$4:$D$855,0),MATCH(CZ$1,$BG$1:$CT$1,0)) -> 0.75394256 | DA6: =INDEX($BG$4:$CT$855,MATCH($CV6,$D$4:$D$855,0),MATCH(DA$1,$BG$1:$CT$1,0)) -> 0.58453565 | DB6: =INDEX($BG$4:$CT$855,MATCH($CV6,$D$4:$D$855,0),MATCH(DB$1,$BG$1:$CT$1,0)) -> 0.014065576 | DC6: =INDEX($BG$4:$CT$855,MATCH($CV6,$D$4:$D$855,0),MATCH(DC$1,$BG$1:$CT$1,0)) -> 0.043822126 | DD6: =INDEX($BG$4:$CT$855,MATCH($CV6,$D$4:$D$855,0),MATCH(DD$1,$BG$1:$CT$1,0)) -> 0.0034050029 | ... DI6: =INDEX($BG$4:$CT$855,MATCH($CV6,$D$4:$D$855,0),MATCH(DI$1,$BG$1:$CT$1,0)) -> 37.085366 | DJ6: =AVERAGE(CW6:DI6) -> 118.42031 | DL6: =DL5+1 -> 3 | DM6: =SMALL($DJ$4:$DJ$855,DL6) -> 0.15762138 | DN6: =INDEX($CV$4:$DJ$855,MATCH($DM6,$DJ$4:$DJ$855,0),1) -> Itabirito | DP6: Brumadinho | DQ6: =INDEX($DL$4:$DN$855,MATCH($DP6,$DN$4:$DN$855,0),1) -> 4
A7: 310040 | B7: Sudeste | C7: MG | D7: Acaiaca | E7: 3567 | F7: 34.77 | G7: 62.72 | H7: 1240.2459 | I7: 2237.2224 | J7: 112.0841 | K7: 3876 | L7: 14.74 | M7: 49.15 | N7: 571.3224 | O7: 1905.054 | P7: 71.2399 | Q7: 3919 | R7: 8.27 | S7: 26.53 | T7: 324.1013 | U7: 1039.7107 | V7: 72.9186 | W7: 0.59 | X7: 0.55 | Y7: 0.48 | Z7: 112.2831 | AA7: 100.5377 | AB7: 97.0911 | AC7: 9353.655 | AD7: 31171.268 | AE7: 2413.8465 | AF7: 7696.61 | AG7: 3875 | AH7: 4050 | AI7: 59.9439 | AJ7: 41.2733 | AK7: 0.336 | AL7: 0.112 | AM7: 0.636 | AN7: 0.533 | AO7: 0.518 | AP7: 0.341 | AQ7: 0.724 | AR7: 0.564 | AS7: 0.63 | AT7: 0.499 | AU7: 0.823 | AV7: 0.61 | AW7: 3211 | AX7: 1810 | AY7: 10233 | AZ7: 15244 | BA7: =AW7/SUM($AW7:$AZ7) -> 0.10528559 | BB7: =AX7/SUM($AW7:$AZ7) -> 0.059348154 | BC7: =AY7/SUM($AW7:$AZ7) -> 0.3355302 | BD7: =AZ7/SUM($AW7:$AZ7) -> 0.49983605 | BG7: =(Q7/Q$2-1)^2 -> 0.85989413 | BH7: =(R7/R$2-1)^2 -> 1.7332423 | BI7: =(S7/S$2-1)^2 -> 1.5968161 | BJ7: =(T7/T$2-1)^2 -> 0.69155783 | BK7: =(U7/U$2-1)^2 -> 0.69796551 | BL7: =(V7/V$2-1)^2 -> 1.7332341 | BM7: =(W7/W$2-1)^2 -> 0.00027777778 | BN7: =(X7/X$2-1)^2 -> 0.001231148 | ... CT7: =(BD7/BD$2-1)^2 -> 121.66369 | CV7: =D7 -> Acaiaca | CW7: =INDEX($BG$4:$CT$855,MATCH($CV7,$D$4:$D$855,0),MATCH(CW$1,$BG$1:$CT$1,0)) -> 1.7332423 | CX7: =INDEX($BG$4:$CT$855,MATCH($CV7,$D$4:$D$855,0),MATCH(CX$1,$BG$1:$CT$1,0)) -> 1.5968161 | CY7: =INDEX($BG$4:$CT$855,MATCH($CV7,$D$4:$D$855,0),MATCH(CY$1,$BG$1:$CT$1,0)) -> 0.0034602076 | CZ7: =INDEX($BG$4:$CT$855,MATCH($CV7,$D$4:$D$855,0),MATCH(CZ$1,$BG$1:$CT$1,0)) -> 0.82909925 | DA7: =INDEX($BG$4:$CT$855,MATCH($CV7,$D$4:$D$855,0),MATCH(DA$1,$BG$1:$CT$1,0)) -> 0.86574056 | DB7: =INDEX($BG$4:$CT$855,MATCH($CV7,$D$4:$D$855,0),MATCH(DB$1,$BG$1:$CT$1,0)) -> 0.022783909 | DC7: =INDEX($BG$4:$CT$855,MATCH($CV7,$D$4:$D$855,0),MATCH(DC$1,$BG$1:$CT$1,0)) -> 0.061749256 | DD7: =INDEX($BG$4:$CT$855,MATCH($CV7,$D$4:$D$855,0),MATCH(DD$1,$BG$1:$CT$1,0)) -> 0.0034050029 | ... DI7: =INDEX($BG$4:$CT$855,MATCH($CV7,$D$4:$D$855,0),MATCH(DI$1,$BG$1:$CT$1,0)) -> 121.66369 | DJ7: =AVERAGE(CW7:DI7) -> 44.347865 | DL7: =DL6+1 -> 4 | DM7: =SMALL($DJ$4:$DJ$855,DL7) -> 0.17297624 | DN7: =INDEX($CV$4:$DJ$855,MATCH($DM7,$DJ$4:$DJ$855,0),1) -> Brumadinho | DP7: Catas Altas | DQ7: =INDEX($DL$4:$DN$855,MATCH($DP7,$DN$4:$DN$855,0),1) -> 56
A8: 310050 | B8: Sudeste | C8: MG | D8: Açucena | E8: 12287 | F8: 43.8 | G8: 77.95 | H8: 5381.706 | I8: 9577.7165 | J8: 141.1931 | K8: 11450 | L8: 30.69 | M8: 57.16 | N8: 3514.005 | O8: 6544.82 | P8: 148.3279 | Q8: 10218 | R8: 15.14 | S8: 30.7 | T8: 1547.0052 | U8: 3136.926 | V8: 133.493 | W8: 0.56 | X8: 0.55 | Y8: 0.48 | Z8: 106.5738 | AA8: 100.5377 | AB8: 97.0911 | AC8: 20922.01 | AD8: 71439.253 | AE8: 1818.5146 | AF8: 6992.88 | AG8: 11505 | AH8: 10216 | AI8: 45.1598 | AJ8: 37.4995 | AK8: 0.267 | AL8: 0.064 | AM8: 0.665 | AN8: 0.447 | AO8: 0.443 | AP8: 0.229 | AQ8: 0.757 | AR8: 0.501 | AS8: 0.61 | AT8: 0.451 | AU8: 0.844 | AV8: 0.595 | AW8: 16057 | AX8: 2196 | AY8: 17486 | AZ8: 33968 | BA8: =AW8/SUM($AW8:$AZ8) -> 0.23034989 | BB8: =AX8/SUM($AW8:$AZ8) -> 0.031503292 | BC8: =AY8/SUM($AW8:$AZ8) -> 0.25084999 | BD8: =AZ8/SUM($AW8:$AZ8) -> 0.48729683 | BG8: =(Q8/Q$2-1)^2 -> 0.65684846 | BH8: =(R8/R$2-1)^2 -> 10.503409 | BI8: =(S8/S$2-1)^2 -> 2.622631 | BJ8: =(T8/T$2-1)^2 -> 0.03848992 | BK8: =(U8/U$2-1)^2 -> 0.25352598 | BL8: =(V8/V$2-1)^2 -> 10.50336 | BM8: =(W8/W$2-1)^2 -> 0.0044444444 | BN8: =(X8/X$2-1)^2 -> 0.001231148 | ... CT8: =(BD8/BD$2-1)^2 -> 115.09708 | CV8: =D8 -> Açucena | CW8: =INDEX($BG$4:$CT$855,MATCH($CV8,$D$4:$D$855,0),MATCH(CW$1,$BG$1:$CT$1,0)) -> 10.503409 | CX8: =INDEX($BG$4:$CT$855,MATCH($CV8,$D$4:$D$855,0),MATCH(CX$1,$BG$1:$CT$1,0)) -> 2.622631 | CY8: =INDEX($BG$4:$CT$855,MATCH($CV8,$D$4:$D$855,0),MATCH(CY$1,$BG$1:$CT$1,0)) -> 0.0034602076 | CZ8: =INDEX($BG$4:$CT$855,MATCH($CV8,$D$4:$D$855,0),MATCH(CZ$1,$BG$1:$CT$1,0)) -> 0.84406064 | DA8: =INDEX($BG$4:$CT$855,MATCH($CV8,$D$4:$D$855,0),MATCH(DA$1,$BG$1:$CT$1,0)) -> 0.67991045 | DB8: =INDEX($BG$4:$CT$855,MATCH($CV8,$D$4:$D$855,0),MATCH(DB$1,$BG$1:$CT$1,0)) -> 0.031647547 | DC8: =INDEX($BG$4:$CT$855,MATCH($CV8,$D$4:$D$855,0),MATCH(DC$1,$BG$1:$CT$1,0)) -> 0.10290182 | DD8: =INDEX($BG$4:$CT$855,MATCH($CV8,$D$4:$D$855,0),MATCH(DD$1,$BG$1:$CT$1,0)) -> 0.0011782017 | ... DI8: =INDEX($BG$4:$CT$855,MATCH($CV8,$D$4:$D$855,0),MATCH(DI$1,$BG$1:$CT$1,0)) -> 115.09708 | DJ8: =AVERAGE(CW8:DI8) -> 183.88214 | DL8: =DL7+1 -> 5 | DM8: =SMALL($DJ$4:$DJ$855,DL8) -> 0.20467983 | DN8: =INDEX($CV$4:$DJ$855,MATCH($DM8,$DJ$4:$DJ$855,0),1) -> Congonhas | DP8: Congonhas | DQ8: =INDEX($DL$4:$DN$855,MATCH($DP8,$DN$4:$DN$855,0),1) -> 5
A9: 310060 | B9: Sudeste | C9: MG | D9: Água Boa | E9: 15684 | F9: 50.37 | G9: 77.45 | H9: 7900.0308 | I9: 12147.258 | J9: 162.3721 | K9: 17402 | L9: 31.59 | M9: 58.85 | N9: 5497.2918 | O9: 10241.077 | P9: 152.6777 | Q9: 15092 | R9: 11.95 | S9: 31.79 | T9: 1803.494 | U9: 4797.7468 | V9: 105.366 | W9: 0.55 | X9: 0.64 | Y9: 0.5 | Z9: 104.6707 | AA9: 116.9893 | AB9: 101.1366 | AC9: 34319.366 | AD9: 112034.74 | AE9: 1938.6187 | AF9: 7541.38 | AG9: 17703 | AH9: 14856 | AI9: 48.1424 | AJ9: 40.4409 | AK9: 0.256 | AL9: 0.056 | AM9: 0.675 | AN9: 0.442 | AO9: 0.451 | AP9: 0.238 | AQ9: 0.702 | AR9: 0.548 | AS9: 0.576 | AT9: 0.403 | AU9: 0.799 | AV9: 0.594 | AW9: 27326 | AX9: 5532 | AY9: 29288 | AZ9: 45929 | BA9: =AW9/SUM($AW9:$AZ9) -> 0.25284293 | BB9: =AX9/SUM($AW9:$AZ9) -> 0.051186676 | BC9: =AY9/SUM($AW9:$AZ9) -> 0.27099699 | BD9: =AZ9/SUM($AW9:$AZ9) -> 0.4249734 | BG9: =(Q9/Q$2-1)^2 -> 0.51847479 | BH9: =(R9/R$2-1)^2 -> 5.5100001 | BI9: =(S9/S$2-1)^2 -> 2.9325101 | BJ9: =(T9/T$2-1)^2 -> 0.0039587947 | BK9: =(U9/U$2-1)^2 -> 0.057913783 | BL9: =(V9/V$2-1)^2 -> 5.5099708 | BM9: =(W9/W$2-1)^2 -> 0.0069444444 | BN9: =(X9/X$2-1)^2 -> 0.015081564 | ... CT9: =(BD9/BD$2-1)^2 -> 85.161913 | CV9: =D9 -> Água Boa | CW9: =INDEX($BG$4:$CT$855,MATCH($CV9,$D$4:$D$855,0),MATCH(CW$1,$BG$1:$CT$1,0)) -> 5.5100001 | CX9: =INDEX($BG$4:$CT$855,MATCH($CV9,$D$4:$D$855,0),MATCH(CX$1,$BG$1:$CT$1,0)) -> 2.9325101 | CY9: =INDEX($BG$4:$CT$855,MATCH($CV9,$D$4:$D$855,0),MATCH(CY$1,$BG$1:$CT$1,0)) -> 0.00038446751 | CZ9: =INDEX($BG$4:$CT$855,MATCH($CV9,$D$4:$D$855,0),MATCH(CZ$1,$BG$1:$CT$1,0)) -> 0.83238796 | DA9: =INDEX($BG$4:$CT$855,MATCH($CV9,$D$4:$D$855,0),MATCH(DA$1,$BG$1:$CT$1,0)) -> 0.55485652 | DB9: =INDEX($BG$4:$CT$855,MATCH($CV9,$D$4:$D$855,0),MATCH(DB$1,$BG$1:$CT$1,0)) -> 0.050050494 | DC9: =INDEX($BG$4:$CT$855,MATCH($CV9,$D$4:$D$855,0),MATCH(DC$1,$BG$1:$CT$1,0)) -> 0.15450582 | DD9: =INDEX($BG$4:$CT$855,MATCH($CV9,$D$4:$D$855,0),MATCH(DD$1,$BG$1:$CT$1,0)) -> 0.0073637606 | ... DI9: =INDEX($BG$4:$CT$855,MATCH($CV9,$D$4:$D$855,0),MATCH(DI$1,$BG$1:$CT$1,0)) -> 85.161913 | DJ9: =AVERAGE(CW9:DI9) -> 217.59863 | DL9: =DL8+1 -> 6 | DM9: =SMALL($DJ$4:$DJ$855,DL9) -> 0.23211201 | DN9: =INDEX($CV$4:$DJ$855,MATCH($DM9,$DJ$4:$DJ$855,0),1) -> Itabira | DP9: Itabira | DQ9: =INDEX($DL$4:$DN$855,MATCH($DP9,$DN$4:$DN$855,0),1) -> 6
A10: 310070 | B10: Sudeste | C10: MG | D10: Água Comprida | E10: 1799 | F10: 9.9 | G10: 34.05 | H10: 178.101 | I10: 612.5595 | J10: 31.9135 | K10: 2083 | L10: 0.85 | M10: 12.56 | N10: 17.7055 | O10: 261.6248 | P10: 4.1081 | Q10: 1997 | R10: 0.71 | S10: 4.39 | T10: 14.1787 | U10: 87.6683 | V10: 6.2602 | W10: 0.46 | X10: 0.47 | Y10: 0.46 | Z10: 87.5428 | AA10: 85.914 | AB10: 93.0457 | AC10: 21032.102 | AD10: 98664.737 | AE10: 10116.451 | AF10: 47733.3 | AG10: 2079 | AH10: 2067 | AI10: 251.2255 | AJ10: 255.9712 | AK10: 0.442 | AL10: 0.199 | AM10: 0.759 | AN10: 0.573 | AO10: 0.604 | AP10: 0.401 | AQ10: 0.82 | AR10: 0.67 | AS10: 0.675 | AT10: 0.498 | AU10: 0.86 | AV10: 0.719 | AW10: 51906 | AX10: 5281 | AY10: 24394 | AZ10: 13870 | BA10: =AW10/SUM($AW10:$AZ10) -> 0.54379734 | BB10: =AX10/SUM($AW10:$AZ10) -> 0.055326817 | BC10: =AY10/SUM($AW10:$AZ10) -> 0.25556568 | BD10: =AZ10/SUM($AW10:$AZ10) -> 0.14531016 | BG10: =(Q10/Q$2-1)^2 -> 0.92728576 | BH10: =(R10/R$2-1)^2 -> 0.64179397 | BI10: =(S10/S$2-1)^2 -> 0.39115846 | BJ10: =(T10/T$2-1)^2 -> 0.98532 | BK10: =(U10/U$2-1)^2 -> 0.97244172 | BL10: =(V10/V$2-1)^2 -> 0.64179657 | BM10: =(W10/W$2-1)^2 -> 0.054444444 | BN10: =(X10/X$2-1)^2 -> 0.030778701 | ... CT10: =(BD10/BD$2-1)^2 -> 6.2367368 | CV10: =D10 -> Água Comprida | CW10: =INDEX($BG$4:$CT$855,MATCH($CV10,$D$4:$D$855,0),MATCH(CW$1,$BG$1:$CT$1,0)) -> 0.64179397 | CX10: =INDEX($BG$4:$CT$855,MATCH($CV10,$D$4:$D$855,0),MATCH(CX$1,$BG$1:$CT$1,0)) -> 0.39115846 | CY10: =INDEX($BG$4:$CT$855,MATCH($CV10,$D$4:$D$855,0),MATCH(CY$1,$BG$1:$CT$1,0)) -> 0.0096116878 | CZ10: =INDEX($BG$4:$CT$855,MATCH($CV10,$D$4:$D$855,0),MATCH(CZ$1,$BG$1:$CT$1,0)) -> 0.19823565 | DA10: =INDEX($BG$4:$CT$855,MATCH($CV10,$D$4:$D$855,0),MATCH(DA$1,$BG$1:$CT$1,0)) -> 0.93026924 | DB10: =INDEX($BG$4:$CT$855,MATCH($CV10,$D$4:$D$855,0),MATCH(DB$1,$BG$1:$CT$1,0)) -> 0.0081534572 | DC10: =INDEX($BG$4:$CT$855,MATCH($CV10,$D$4:$D$855,0),MATCH(DC$1,$BG$1:$CT$1,0)) -> 0.0625 | DD10: =INDEX($BG$4:$CT$855,MATCH($CV10,$D$4:$D$855,0),MATCH(DD$1,$BG$1:$CT$1,0)) -> 0.00025658615 | ... DI10: =INDEX($BG$4:$CT$855,MATCH($CV10,$D$4:$D$855,0),MATCH(DI$1,$BG$1:$CT$1,0)) -> 6.2367368 | DJ10: =AVERAGE(CW10:DI10) -> 993.06527 | DL10: =DL9+1 -> 7 | DM10: =SMALL($DJ$4:$DJ$855,DL10) -> 0.25352585 | DN10: =INDEX($CV$4:$DJ$855,MATCH($DM10,$DJ$4:$DJ$855,0),1) -> Nova Lima | DP10: Itabirito | DQ10: =INDEX($DL$4:$DN$855,MATCH($DP10,$DN$4:$DN$855,0),1) -> 3
A11: 310080 | B11: Sudeste | C11: MG | D11: Aguanil | E11: 3197 | F11: 16.94 | G11: 49.87 | H11: 541.5718 | I11: 1594.3439 | J11: 54.6076 | K11: 3543 | L11: 2.18 | M11: 17.36 | N11: 77.2374 | O11: 615.0648 | P11: 10.5362 | Q11: 4039 | R11: 2.74 | S11: 8.51 | T11: 110.6686 | U11: 343.7189 | V11: 24.1592 | W11: 0.44 | X11: 0.48 | Y11: 0.45 | Z11: 83.7366 | AA11: 87.742 | AB11: 91.0229 | AC11: 10524.952 | AD11: 47677.248 | AE11: 2968.9568 | AF11: 11005.83 | AG11: 3545 | AH11: 4332 | AI11: 73.7292 | AJ11: 59.0191 | AK11: 0.405 | AL11: 0.183 | AM11: 0.703 | AN11: 0.515 | AO11: 0.574 | AP11: 0.373 | AQ11: 0.798 | AR11: 0.637 | AS11: 0.663 | AT11: 0.513 | AU11: 0.845 | AV11: 0.672 | AW11: 10824 | AX11: 3271 | AY11: 15078 | AZ11: 17094 | BA11: =AW11/SUM($AW11:$AZ11) -> 0.23394644 | BB11: =AX11/SUM($AW11:$AZ11) -> 0.070698338 | BC11: =AY11/SUM($AW11:$AZ11) -> 0.32589102 | BD11: =AZ11/SUM($AW11:$AZ11) -> 0.3694642 | BG11: =(Q11/Q$2-1)^2 -> 0.85577085 | BH11: =(R11/R$2-1)^2 -> 0.054052994 | BI11: =(S11/S$2-1)^2 -> 0.075016162 | BJ11: =(T11/T$2-1)^2 -> 0.8883015 | BK11: =(U11/U$2-1)^2 -> 0.89415757 | BL11: =(V11/V$2-1)^2 -> 0.054054152 | BM11: =(W11/W$2-1)^2 -> 0.071111111 | BN11: =(X11/X$2-1)^2 -> 0.024930748 | ... CT11: =(BD11/BD$2-1)^2 -> 62.28868 | CV11: =D11 -> Aguanil | CW11: =INDEX($BG$4:$CT$855,MATCH($CV11,$D$4:$D$855,0),MATCH(CW$1,$BG$1:$CT$1,0)) -> 0.054052994 | CX11: =INDEX($BG$4:$CT$855,MATCH($CV11,$D$4:$D$855,0),MATCH(CX$1,$BG$1:$CT$1,0)) -> 0.075016162 | CY11: =INDEX($BG$4:$CT$855,MATCH($CV11,$D$4:$D$855,0),MATCH(CY$1,$BG$1:$CT$1,0)) -> 0.01384083 | CZ11: =INDEX($BG$4:$CT$855,MATCH($CV11,$D$4:$D$855,0),MATCH(CZ$1,$BG$1:$CT$1,0)) -> 0.76053859 | DA11: =INDEX($BG$4:$CT$855,MATCH($CV11,$D$4:$D$855,0),MATCH(DA$1,$BG$1:$CT$1,0)) -> 0.85675237 | DB11: =INDEX($BG$4:$CT$855,MATCH($CV11,$D$4:$D$855,0),MATCH(DB$1,$BG$1:$CT$1,0)) -> 0.011335649 | DC11: =INDEX($BG$4:$CT$855,MATCH($CV11,$D$4:$D$855,0),MATCH(DC$1,$BG$1:$CT$1,0)) -> 0.051715144 | DD11: =INDEX($BG$4:$CT$855,MATCH($CV11,$D$4:$D$855,0),MATCH(DD$1,$BG$1:$CT$1,0)) -> 0.001100964 | ... DI11: =INDEX($BG$4:$CT$855,MATCH($CV11,$D$4:$D$855,0),MATCH(DI$1,$BG$1:$CT$1,0)) -> 62.28868 | DJ11: =AVERAGE(CW11:DI11) -> 184.40635 | DL11: =DL10+1 -> 8 | DM11: =SMALL($DJ$4:$DJ$855,DL11) -> 0.25688168 | DN11: =INDEX($CV$4:$DJ$855,MATCH($DM11,$DJ$4:$DJ$855,0),1) -> Belo Oriente | DP11: Jeceaba | DQ11: =INDEX($DL$4:$DN$855,MATCH($DP11,$DN$4:$DN$855,0),1) -> 32
A12: 310090 | B12: Sudeste | C12: MG | D12: Águas Formosas | E12: 16529 | F12: 45.54 | G12: 74.03 | H12: 7527.3066 | I12: 12236.419 | J12: 146.8021 | K12: 17473 | L12: 38.15 | M12: 61.25 | N12: 6665.9495 | O12: 10702.213 | P12: 184.3828 | Q12: 18362 | R12: 13.67 | S12: 31.69 | T12: 2510.0854 | U12: 5818.9178 | V12: 120.5317 | W12: 0.64 | X12: 0.65 | Y12: 0.57 | Z12: 121.7987 | AA12: 118.8173 | AB12: 115.2957 | AC12: 31264.787 | AD12: 184517.11 | AE12: 1755.5611 | AF12: 9586.3 | AG12: 17809 | AH12: 19248 | AI12: 43.5965 | AJ12: 51.4068 | AK12: 0.382 | AL12: 0.176 | AM12: 0.625 | AN12: 0.508 | AO12: 0.508 | AP12: 0.344 | AQ12: 0.711 | AR12: 0.537 | AS12: 0.645 | AT12: 0.531 | AU12: 0.811 | AV12: 0.624 | AW12: 11378 | AX12: 15162 | AY12: 85761 | AZ12: 60789 | BA12: =AW12/SUM($AW12:$AZ12) -> 0.065734589 | BB12: =AX12/SUM($AW12:$AZ12) -> 0.087596048 | BC12: =AY12/SUM($AW12:$AZ12) -> 0.49547056 | BD12: =AZ12/SUM($AW12:$AZ12) -> 0.3511988 | BG12: =(Q12/Q$2-1)^2 -> 0.43480215 | BH12: =(R12/R$2-1)^2 -> 8.0039859 | BI12: =(S12/S$2-1)^2 -> 2.9033601 | BJ12: =(T12/T$2-1)^2 -> 0.09254998 | BK12: =(U12/U$2-1)^2 -> 0.0062458096 | BL12: =(V12/V$2-1)^2 -> 8.0039545 | BM12: =(W12/W$2-1)^2 -> 0.0044444444 | BN12: =(X12/X$2-1)^2 -> 0.019698369 | ... CT12: =(BD12/BD$2-1)^2 -> 55.54279 | CV12: =D12 -> Águas Formosas | CW12: =INDEX($BG$4:$CT$855,MATCH($CV12,$D$4:$D$855,0),MATCH(CW$1,$BG$1:$CT$1,0)) -> 8.0039859 | CX12: =INDEX($BG$4:$CT$855,MATCH($CV12,$D$4:$D$855,0),MATCH(CX$1,$BG$1:$CT$1,0)) -> 2.9033601 | CY12: =INDEX($BG$4:$CT$855,MATCH($CV12,$D$4:$D$855,0),MATCH(CY$1,$BG$1:$CT$1,0)) -> 0.01384083 | CZ12: =INDEX($BG$4:$CT$855,MATCH($CV12,$D$4:$D$855,0),MATCH(CZ$1,$BG$1:$CT$1,0)) -> 0.78958619 | DA12: =INDEX($BG$4:$CT$855,MATCH($CV12,$D$4:$D$855,0),MATCH(DA$1,$BG$1:$CT$1,0)) -> 0.44818441 | DB12: =INDEX($BG$4:$CT$855,MATCH($CV12,$D$4:$D$855,0),MATCH(DB$1,$BG$1:$CT$1,0)) -> 0.017089748 | DC12: =INDEX($BG$4:$CT$855,MATCH($CV12,$D$4:$D$855,0),MATCH(DC$1,$BG$1:$CT$1,0)) -> 0.040120573 | DD12: =INDEX($BG$4:$CT$855,MATCH($CV12,$D$4:$D$855,0),MATCH(DD$1,$BG$1:$CT$1,0)) -> 0.0051958695 | ... DI12: =INDEX($BG$4:$CT$855,MATCH($CV12,$D$4:$D$855,0),MATCH(DI$1,$BG$1:$CT$1,0)) -> 55.54279 | DJ12: =AVERAGE(CW12:DI12) -> 18.049997 | DL12: =DL11+1 -> 9 | DM12: =SMALL($DJ$4:$DJ$855,DL12) -> 0.28690158 | DN12: =INDEX($CV$4:$DJ$855,MATCH($DM12,$DJ$4:$DJ$855,0),1) -> Rio Piracicaba | DP12: Nova Lima | DQ12: =INDEX($DL$4:$DN$855,MATCH($DP12,$DN$4:$DN$855,0),1) -> 7
A13: 310100 | B13: Sudeste | C13: MG | D13: Águas Vermelhas | E13: 10733 | F13: 36.28 | G13: 66.3 | H13: 3893.9324 | I13: 7115.979 | J13: 116.9517 | K13: 11753 | L13: 36.84 | M13: 61.01 | N13: 4329.8052 | O13: 7170.5053 | P13: 178.0515 | Q13: 12696 | R13: 11.41 | S13: 33.19 | T13: 1448.6136 | U13: 4213.8024 | V13: 100.6047 | W13: 0.61 | X13: 0.6 | Y13: 0.51 | Z13: 116.0894 | AA13: 109.6775 | AB13: 103.1593 | AC13: 26126.92 | AD13: 155814.46 | AE13: 2213.208 | AF13: 11647.07 | AG13: 11805 | AH13: 13378 | AI13: 54.9614 | AJ13: 62.4578 | AK13: 0.33 | AL13: 0.118 | AM13: 0.589 | AN13: 0.519 | AO13: 0.466 | AP13: 0.283 | AQ13: 0.702 | AR13: 0.509 | AS13: 0.601 | AT13: 0.458 | AU13: 0.808 | AV13: 0.586 | AW13: 17810 | AX13: 9270 | AY13: 73347 | AZ13: 40904 | BA13: =AW13/SUM($AW13:$AZ13) -> 0.12601623 | BB13: =AX13/SUM($AW13:$AZ13) -> 0.065590706 | BC13: =AY13/SUM($AW13:$AZ13) -> 0.51897319 | BD13: =AZ13/SUM($AW13:$AZ13) -> 0.28941987 | BG13: =(Q13/Q$2-1)^2 -> 0.58445472 | BH13: =(R13/R$2-1)^2 -> 4.8227605 | BI13: =(S13/S$2-1)^2 -> 3.3558989 | BJ13: =(T13/T$2-1)^2 -> 0.06116321 | BK13: =(U13/U$2-1)^2 -> 0.11093873 | BL13: =(V13/V$2-1)^2 -> 4.8227356 | BM13: =(W13/W$2-1)^2 -> 0.00027777778 | BN13: =(X13/X$2-1)^2 -> 0.0027700831 | ... CT13: =(BD13/BD$2-1)^2 -> 35.590762 | CV13: =D13 -> Águas Vermelhas | CW13: =INDEX($BG$4:$CT$855,MATCH($CV13,$D$4:$D$855,0),MATCH(CW$1,$BG$1:$CT$1,0)) -> 4.8227605 | CX13: =INDEX($BG$4:$CT$855,MATCH($CV13,$D$4:$D$855,0),MATCH(CX$1,$BG$1:$CT$1,0)) -> 3.3558989 | CY13: =INDEX($BG$4:$CT$855,MATCH($CV13,$D$4:$D$855,0),MATCH(CY$1,$BG$1:$CT$1,0)) -> 0 | CZ13: =INDEX($BG$4:$CT$855,MATCH($CV13,$D$4:$D$855,0),MATCH(CZ$1,$BG$1:$CT$1,0)) -> 0.7475955 | DA13: =INDEX($BG$4:$CT$855,MATCH($CV13,$D$4:$D$855,0),MATCH(DA$1,$BG$1:$CT$1,0)) -> 0.59331236 | DB13: =INDEX($BG$4:$CT$855,MATCH($CV13,$D$4:$D$855,0),MATCH(DB$1,$BG$1:$CT$1,0)) -> 0.036110243 | DC13: =INDEX($BG$4:$CT$855,MATCH($CV13,$D$4:$D$855,0),MATCH(DC$1,$BG$1:$CT$1,0)) -> 0.096249456 | DD13: =INDEX($BG$4:$CT$855,MATCH($CV13,$D$4:$D$855,0),MATCH(DD$1,$BG$1:$CT$1,0)) -> 0.0057024962 | ... DI13: =INDEX($BG$4:$CT$855,MATCH($CV13,$D$4:$D$855,0),MATCH(DI$1,$BG$1:$CT$1,0)) -> 35.590762 | DJ13: =AVERAGE(CW13:DI13) -> 53.859662 | DL13: =DL12+1 -> 10 | DM13: =SMALL($DJ$4:$DJ$855,DL13) -> 0.39528848 | DN13: =INDEX($CV$4:$DJ$855,MATCH($DM13,$DJ$4:$DJ$855,0),1) -> Extrema | DP13: Ouro Preto | DQ13: =INDEX($DL$4:$DN$855,MATCH($DP13,$DN$4:$DN$855,0),1) -> 1
A14: 310110 | B14: Sudeste | C14: MG | D14: Aimorés | E14: 26178 | F14: 22.02 | G14: 53.47 | H14: 5764.3956 | I14: 13997.377 | J14: 70.9834 | K14: 24936 | L14: 10.47 | M14: 34.75 | N14: 2610.7992 | O14: 8665.26 | P14: 50.6026 | Q14: 24786 | R14: 4.99 | S14: 14.09 | T14: 1236.8214 | U14: 3492.3474 | V14: 43.998 | W14: 0.56 | X14: 0.56 | Y14: 0.53 | Z14: 106.5738 | AA14: 102.3657 | AB14: 107.2048 | AC14: 77459.897 | AD14: 361772.79 | AE14: 3077.9582 | AF14: 14084.98 | AG14: 25166 | AH14: 25685 | AI14: 76.4361 | AJ14: 75.5311 | AK14: 0.429 | AL14: 0.213 | AM14: 0.679 | AN14: 0.545 | AO14: 0.593 | AP14: 0.437 | AQ14: 0.783 | AR14: 0.609 | AS14: 0.684 | AT14: 0.576 | AU14: 0.81 | AV14: 0.685 | AW14: 45357 | AX14: 78877 | AY14: 149088 | AZ14: 72105 | BA14: =AW14/SUM($AW14:$AZ14) -> 0.13130705 | BB14: =AX14/SUM($AW14:$AZ14) -> 0.22834637 | BC14: =AY14/SUM($AW14:$AZ14) -> 0.43160494 | BD14: =AZ14/SUM($AW14:$AZ14) -> 0.20874164 | BG14: =(Q14/Q$2-1)^2 -> 0.29185248 | BH14: =(R14/R$2-1)^2 -> 0.1582123 | BI14: =(S14/S$2-1)^2 -> 0.040892293 | BJ14: =(T14/T$2-1)^2 -> 0.12770438 | BK14: =(U14/U$2-1)^2 -> 0.20004196 | BL14: =(V14/V$2-1)^2 -> 0.15820973 | BM14: =(W14/W$2-1)^2 -> 0.0044444444 | BN14: =(X14/X$2-1)^2 -> 0.00030778701 | ... CT14: =(BD14/BD$2-1)^2 -> 16.19277 | CV14: =D14 -> Aimorés | CW14: =INDEX($BG$4:$CT$855,MATCH($CV14,$D$4:$D$855,0),MATCH(CW$1,$BG$1:$CT$1,0)) -> 0.1582123 | CX14: =INDEX($BG$4:$CT$855,MATCH($CV14,$D$4:$D$855,0),MATCH(CX$1,$BG$1:$CT$1,0)) -> 0.040892293 | CY14: =INDEX($BG$4:$CT$855,MATCH($CV14,$D$4:$D$855,0),MATCH(CY$1,$BG$1:$CT$1,0)) -> 0.00153787 | CZ14: =INDEX($BG$4:$CT$855,MATCH($CV14,$D$4:$D$855,0),MATCH(CZ$1,$BG$1:$CT$1,0)) -> 0.69940155 | DA14: =INDEX($BG$4:$CT$855,MATCH($CV14,$D$4:$D$855,0),MATCH(DA$1,$BG$1:$CT$1,0)) -> 0.31239947 | DB14: =INDEX($BG$4:$CT$855,MATCH($CV14,$D$4:$D$855,0),MATCH(DB$1,$BG$1:$CT$1,0)) -> 0.006110098 | DC14: =INDEX($BG$4:$CT$855,MATCH($CV14,$D$4:$D$855,0),MATCH(DC$1,$BG$1:$CT$1,0)) -> 0.017564233 | DD14: =INDEX($BG$4:$CT$855,MATCH($CV14,$D$4:$D$855,0),MATCH(DD$1,$BG$1:$CT$1,0)) -> 0.0053621268 | ... DI14: =INDEX($BG$4:$CT$855,MATCH($CV14,$D$4:$D$855,0),MATCH(DI$1,$BG$1:$CT$1,0)) -> 16.19277 | DJ14: =AVERAGE(CW14:DI14) -> 56.119184 | DL14: =DL13+1 -> 11 | DM14: =SMALL($DJ$4:$DJ$855,DL14) -> 0.43765631 | DN14: =INDEX($CV$4:$DJ$855,MATCH($DM14,$DJ$4:$DJ$855,0),1) -> São Gonçalo do Rio Abaixo | DP14: Rio Acima | DQ14: =INDEX($DL$4:$DN$855,MATCH($DP14,$DN$4:$DN$855,0),1) -> 66
A15: 310120 | B15: Sudeste | C15: MG | D15: Aiuruoca | E15: 6564 | F15: 16.44 | G15: 49.86 | H15: 1079.1216 | I15: 3272.8104 | J15: 52.9958 | K15: 6297 | L15: 9.63 | M15: 33.23 | N15: 606.4011 | O15: 2092.4931 | P15: 46.5428 | Q15: 6066 | R15: 1.85 | S15: 11.7 | T15: 112.221 | U15: 709.722 | V15: 16.3119 | W15: 0.55 | X15: 0.63 | Y15: 0.49 | Z15: 104.6707 | AA15: 115.1614 | AB15: 99.1139 | AC15: 20805.718 | AD15: 70051.4 | AE15: 3212.7421 | AF15: 11195.68 | AG15: 6476 | AH15: 6257 | AI15: 79.7832 | AJ15: 60.0372 | AK15: 0.377 | AL15: 0.138 | AM15: 0.697 | AN15: 0.556 | AO15: 0.55 | AP15: 0.327 | AQ15: 0.787 | AR15: 0.647 | AS15: 0.668 | AT15: 0.505 | AU15: 0.871 | AV15: 0.677 | AW15: 15500 | AX15: 3795 | AY15: 26048 | AZ15: 21700 | BA15: =AW15/SUM($AW15:$AZ15) -> 0.2311949 | BB15: =AX15/SUM($AW15:$AZ15) -> 0.056605462 | BC15: =AY15/SUM($AW15:$AZ15) -> 0.38852677 | BD15: =AZ15/SUM($AW15:$AZ15) -> 0.32367287 | BG15: =(Q15/Q$2-1)^2 -> 0.78761921 | BH15: =(R15/R$2-1)^2 -> 0.23212422 | BI15: =(S15/S$2-1)^2 -> 2.9120898e-06 | BJ15: =(T15/T$2-1)^2 -> 0.88678169 | BK15: =(U15/U$2-1)^2 -> 0.78796007 | BL15: =(V15/V$2-1)^2 -> 0.23212488 | BM15: =(W15/W$2-1)^2 -> 0.0069444444 | BN15: =(X15/X$2-1)^2 -> 0.011080332 | ... CT15: =(BD15/BD$2-1)^2 -> 46.106889 | CV15: =D15 -> Aiuruoca | CW15: =INDEX($BG$4:$CT$855,MATCH($CV15,$D$4:$D$855,0),MATCH(CW$1,$BG$1:$CT$1,0)) -> 0.23212422 | CX15: =INDEX($BG$4:$CT$855,MATCH($CV15,$D$4:$D$855,0),MATCH(CX$1,$BG$1:$CT$1,0)) -> 2.9120898e-06 | CY15: =INDEX($BG$4:$CT$855,MATCH($CV15,$D$4:$D$855,0),MATCH(CY$1,$BG$1:$CT$1,0)) -> 0.00153787 | CZ15: =INDEX($BG$4:$CT$855,MATCH($CV15,$D$4:$D$855,0),MATCH(CZ$1,$BG$1:$CT$1,0)) -> 0.756695 | DA15: =INDEX($BG$4:$CT$855,MATCH($CV15,$D$4:$D$855,0),MATCH(DA$1,$BG$1:$CT$1,0)) -> 0.79664967 | DB15: =INDEX($BG$4:$CT$855,MATCH($CV15,$D$4:$D$855,0),MATCH(DB$1,$BG$1:$CT$1,0)) -> 0.0099461643 | DC15: =INDEX($BG$4:$CT$855,MATCH($CV15,$D$4:$D$855,0),MATCH(DC$1,$BG$1:$CT$1,0)) -> 0.057340053 | DD15: =INDEX($BG$4:$CT$855,MATCH($CV15,$D$4:$D$855,0),MATCH(DD$1,$BG$1:$CT$1,0)) -> 1.1782017e-05 | ... DI15: =INDEX($BG$4:$CT$855,MATCH($CV15,$D$4:$D$855,0),MATCH(DI$1,$BG$1:$CT$1,0)) -> 46.106889 | DJ15: =AVERAGE(CW15:DI15) -> 178.90164 | DL15: =DL14+1 -> 12 | DM15: =SMALL($DJ$4:$DJ$855,DL15) -> 0.47392353 | DN15: =INDEX($CV$4:$DJ$855,MATCH($DM15,$DJ$4:$DJ$855,0),1) -> Juatuba | DP15: Rio Paranaíba | DQ15: =INDEX($DL$4:$DN$855,MATCH($DP15,$DN$4:$DN$855,0),1) -> 839
A16: 310130 | B16: Sudeste | C16: MG | D16: Alagoa | E16: 2737 | F16: 23.47 | G16: 54.98 | H16: 642.3739 | I16: 1504.8026 | J16: 75.6576 | K16: 2785 | L16: 21 | M16: 39.39 | N16: 584.85 | O16: 1097.0115 | P16: 101.4951 | Q16: 2675 | R16: 4.19 | S16: 17.57 | T16: 112.0825 | U16: 469.9975 | V16: 36.9442 | W16: 0.62 | X16: 0.53 | Y16: 0.42 | Z16: 117.9925 | AA16: 96.8818 | AB16: 84.9547 | AC16: 6159.496 | AD16: 28271.31 | AE16: 2201.3924 | AF16: 10228.4 | AG16: 2798 | AH16: 2764 | AI16: 54.668 | AJ16: 54.8501 | AK16: 0.441 | AL16: 0.222 | AM16: 0.675 | AN16: 0.573 | AO16: 0.542 | AP16: 0.358 | AQ16: 0.776 | AR16: 0.572 | AS16: 0.649 | AT16: 0.518 | AU16: 0.832 | AV16: 0.634 | AW16: 5778 | AX16: 883 | AY16: 7329 | AZ16: 13379 | BA16: =AW16/SUM($AW16:$AZ16) -> 0.21111476 | BB16: =AX16/SUM($AW16:$AZ16) -> 0.032262779 | BC16: =AY16/SUM($AW16:$AZ16) -> 0.26778472 | BD16: =AZ16/SUM($AW16:$AZ16) -> 0.48883774 | BG16: =(Q16/Q$2-1)^2 -> 0.90322265 | BH16: =(R16/R$2-1)^2 -> 0.030161084 | BI16: =(S16/S$2-1)^2 -> 0.24914749 | BJ16: =(T16/T$2-1)^2 -> 0.88691723 | BK16: =(U16/U$2-1)^2 -> 0.85675893 | BL16: =(V16/V$2-1)^2 -> 0.030160002 | BM16: =(W16/W$2-1)^2 -> 0.0011111111 | BN16: =(X16/X$2-1)^2 -> 0.0049245922 | ... CT16: =(BD16/BD$2-1)^2 -> 115.89421 | CV16: =D16 -> Alagoa | CW16: =INDEX($BG$4:$CT$855,MATCH($CV16,$D$4:$D$855,0),MATCH(CW$1,$BG$1:$CT$1,0)) -> 0.030161084 | CX16: =INDEX($BG$4:$CT$855,MATCH($CV16,$D$4:$D$855,0),MATCH(CX$1,$BG$1:$CT$1,0)) -> 0.24914749 | CY16: =INDEX($BG$4:$CT$855,MATCH($CV16,$D$4:$D$855,0),MATCH(CY$1,$BG$1:$CT$1,0)) -> 0.031141869 | CZ16: =INDEX($BG$4:$CT$855,MATCH($CV16,$D$4:$D$855,0),MATCH(CZ$1,$BG$1:$CT$1,0)) -> 0.77637958 | DA16: =INDEX($BG$4:$CT$855,MATCH($CV16,$D$4:$D$855,0),MATCH(DA$1,$BG$1:$CT$1,0)) -> 0.90732389 | DB16: =INDEX($BG$4:$CT$855,MATCH($CV16,$D$4:$D$855,0),MATCH(DB$1,$BG$1:$CT$1,0)) -> 0.015709345 | DC16: =INDEX($BG$4:$CT$855,MATCH($CV16,$D$4:$D$855,0),MATCH(DC$1,$BG$1:$CT$1,0)) -> 0.048347002 | DD16: =INDEX($BG$4:$CT$855,MATCH($CV16,$D$4:$D$855,0),MATCH(DD$1,$BG$1:$CT$1,0)) -> 0.0023092753 | ... DI16: =INDEX($BG$4:$CT$855,MATCH($CV16,$D$4:$D$855,0),MATCH(DI$1,$BG$1:$CT$1,0)) -> 115.89421 | DJ16: =AVERAGE(CW16:DI16) -> 154.58724 | DL16: =DL15+1 -> 13 | DM16: =SMALL($DJ$4:$DJ$855,DL16) -> 0.50967337 | DN16: =INDEX($CV$4:$DJ$855,MATCH($DM16,$DJ$4:$DJ$855,0),1) -> Timóteo | DP16: Santa Bárbara | DQ16: =INDEX($DL$4:$DN$855,MATCH($DP16,$DN$4:$DN$855,0),1) -> 60
A17: 310140 | B17: Sudeste | C17: MG | D17: Albertina | E17: 2456 | F17: 3.26 | G17: 21.13 | H17: 80.0656 | I17: 518.9528 | J17: 10.5089 | K17: 2822 | L17: 0 | M17: 7.06 | N17: 0 | O17: 199.2332 | P17: 0 | Q17: 2899 | R17: 0.11 | S17: 3.02 | T17: 3.1889 | U17: 87.5498 | V17: 0.9699 | W17: 0.4 | X17: 0.39 | Y17: 0.35 | Z17: 76.1242 | AA17: 71.2904 | AB17: 70.7956 | AC17: 15167.936 | AD17: 72027.224 | AE17: 5369.1809 | AF17: 23810.65 | AG17: 2825 | AH17: 3025 | AI17: 133.3348 | AJ17: 127.6853 | AK17: 0.403 | AL17: 0.148 | AM17: 0.744 | AN17: 0.594 | AO17: 0.546 | AP17: 0.324 | AQ17: 0.79 | AR17: 0.637 | AS17: 0.673 | AT17: 0.549 | AU17: 0.813 | AV17: 0.684 | AW17: 8498 | AX17: 2570 | AY17: 38473 | AZ17: 13039 | BA17: =AW17/SUM($AW17:$AZ17) -> 0.13579418 | BB17: =AX17/SUM($AW17:$AZ17) -> 0.041067434 | BC17: =AY17/SUM($AW17:$AZ17) -> 0.61478108 | BD17: =AZ17/SUM($AW17:$AZ17) -> 0.2083573 | BG17: =(Q17/Q$2-1)^2 -> 0.89534211 | BH17: =(R17/R$2-1)^2 -> 0.93932475 | BI17: =(S17/S$2-1)^2 -> 0.5510402 | BJ17: =(T17/T$2-1)^2 -> 0.99668889 | BK17: =(U17/U$2-1)^2 -> 0.97247871 | BL17: =(V17/V$2-1)^2 -> 0.93932463 | BM17: =(W17/W$2-1)^2 -> 0.11111111 | BN17: =(X17/X$2-1)^2 -> 0.099722992 | ... CT17: =(BD17/BD$2-1)^2 -> 16.118408 | CV17: =D17 -> Albertina | CW17: =INDEX($BG$4:$CT$855,MATCH($CV17,$D$4:$D$855,0),MATCH(CW$1,$BG$1:$CT$1,0)) -> 0.93932475 | CX17: =INDEX($BG$4:$CT$855,MATCH($CV17,$D$4:$D$855,0),MATCH(CX$1,$BG$1:$CT$1,0)) -> 0.5510402 | CY17: =INDEX($BG$4:$CT$855,MATCH($CV17,$D$4:$D$855,0),MATCH(CY$1,$BG$1:$CT$1,0)) -> 0.098423683 | CZ17: =INDEX($BG$4:$CT$855,MATCH($CV17,$D$4:$D$855,0),MATCH(CZ$1,$BG$1:$CT$1,0)) -> 0.52311827 | DA17: =INDEX($BG$4:$CT$855,MATCH($CV17,$D$4:$D$855,0),MATCH(DA$1,$BG$1:$CT$1,0)) -> 0.89880546 | DB17: =INDEX($BG$4:$CT$855,MATCH($CV17,$D$4:$D$855,0),MATCH(DB$1,$BG$1:$CT$1,0)) -> 0.008647496 | DC17: =INDEX($BG$4:$CT$855,MATCH($CV17,$D$4:$D$855,0),MATCH(DC$1,$BG$1:$CT$1,0)) -> 0.029995736 | DD17: =INDEX($BG$4:$CT$855,MATCH($CV17,$D$4:$D$855,0),MATCH(DD$1,$BG$1:$CT$1,0)) -> 0.0048712095 | ... DI17: =INDEX($BG$4:$CT$855,MATCH($CV17,$D$4:$D$855,0),MATCH(DI$1,$BG$1:$CT$1,0)) -> 16.118408 | DJ17: =AVERAGE(CW17:DI17) -> 60.357251 | DL17: =DL16+1 -> 14 | DM17: =SMALL($DJ$4:$DJ$855,DL17) -> 0.52088094 | DN17: =INDEX($CV$4:$DJ$855,MATCH($DM17,$DJ$4:$DJ$855,0),1) -> Pirapetinga | DP17: São Gonçalo do Rio Abaixo | DQ17: =INDEX($DL$4:$DN$855,MATCH($DP17,$DN$4:$DN$855,0),1) -> 11
A18: 310150 | B18: Sudeste | C18: MG | D18: Além Paraíba | E18: 30503 | F18: 8.05 | G18: 30.72 | H18: 2455.4915 | I18: 9370.5216 | J18: 25.9499 | K18: 33442 | L18: 4.25 | M18: 18.1 | N18: 1421.285 | O18: 6053.002 | P18: 20.5407 | Q18: 34233 | R18: 2.29 | S18: 9.22 | T18: 783.9357 | U18: 3156.2826 | V18: 20.1915 | W18: 0.55 | X18: 0.56 | Y18: 0.5 | Z18: 104.6707 | AA18: 102.3657 | AB18: 101.1366 | AC18: 181603.2 | AD18: 740158.05 | AE18: 5422.9336 | AF18: 20767.04 | AG18: 33488 | AH18: 35641 | AI18: 134.6697 | AJ18: 111.3639 | AK18: 0.553 | AL18: 0.383 | AM18: 0.704 | AN18: 0.628 | AO18: 0.65 | AP18: 0.524 | AQ18: 0.759 | AR18: 0.689 | AS18: 0.726 | AT18: 0.626 | AU18: 0.857 | AV18: 0.713 | AW18: 6819 | AX18: 83866 | AY18: 457695 | AZ18: 110670 | BA18: =AW18/SUM($AW18:$AZ18) -> 0.010346711 | BB18: =AX18/SUM($AW18:$AZ18) -> 0.12725286 | BC18: =AY18/SUM($AW18:$AZ18) -> 0.6944769 | BD18: =AZ18/SUM($AW18:$AZ18) -> 0.16792353 | BG18: =(Q18/Q$2-1)^2 -> 0.13322297 | BH18: =(R18/R$2-1)^2 -> 0.12855338 | BI18: =(S18/S$2-1)^2 -> 0.045501404 | BJ18: =(T18/T$2-1)^2 -> 0.35126162 | BK18: =(U18/U$2-1)^2 -> 0.25045023 | BL18: =(V18/V$2-1)^2 -> 0.12855369 | BM18: =(W18/W$2-1)^2 -> 0.0069444444 | BN18: =(X18/X$2-1)^2 -> 0.00030778701 | ... CT18: =(BD18/BD$2-1)^2 -> 9.2513776 | CV18: =D18 -> Além Paraíba | CW18: =INDEX($BG$4:$CT$855,MATCH($CV18,$D$4:$D$855,0),MATCH(CW$1,$BG$1:$CT$1,0)) -> 0.12855338 | CX18: =INDEX($BG$4:$CT$855,MATCH($CV18,$D$4:$D$855,0),MATCH(CX$1,$BG$1:$CT$1,0)) -> 0.045501404 | CY18: =INDEX($BG$4:$CT$855,MATCH($CV18,$D$4:$D$855,0),MATCH(CY$1,$BG$1:$CT$1,0)) -> 0.00038446751 | CZ18: =INDEX($BG$4:$CT$855,MATCH($CV18,$D$4:$D$855,0),MATCH(CZ$1,$BG$1:$CT$1,0)) -> 0.57553834 | DA18: =INDEX($BG$4:$CT$855,MATCH($CV18,$D$4:$D$855,0),MATCH(DA$1,$BG$1:$CT$1,0)) -> 0.15051197 | DB18: =INDEX($BG$4:$CT$855,MATCH($CV18,$D$4:$D$855,0),MATCH(DB$1,$BG$1:$CT$1,0)) -> 0.00046497773 | DC18: =INDEX($BG$4:$CT$855,MATCH($CV18,$D$4:$D$855,0),MATCH(DC$1,$BG$1:$CT$1,0)) -> 0.0032751488 | DD18: =INDEX($BG$4:$CT$855,MATCH($CV18,$D$4:$D$855,0),MATCH(DD$1,$BG$1:$CT$1,0)) -> 0.00037833366 | ... DI18: =INDEX($BG$4:$CT$855,MATCH($CV18,$D$4:$D$855,0),MATCH(DI$1,$BG$1:$CT$1,0)) -> 9.2513776 | DJ18: =AVERAGE(CW18:DI18) -> 1.1841041 | DL18: =DL17+1 -> 15 | DM18: =SMALL($DJ$4:$DJ$855,DL18) -> 0.54543313 | DN18: =INDEX($CV$4:$DJ$855,MATCH($DM18,$DJ$4:$DJ$855,0),1) -> Itajubá
A19: 310160 | B19: Sudeste | C19: MG | D19: Alfenas | E19: 51980 | F19: 4.9 | G19: 21.81 | H19: 2547.02 | I19: 11336.838 | J19: 15.7956 | K19: 66506 | L19: 1.95 | M19: 10.28 | N19: 1296.867 | O19: 6836.8168 | P19: 9.4245 | Q19: 73347 | R19: 0.48 | S19: 5.53 | T19: 352.0656 | U19: 4056.0891 | V19: 4.2323 | W19: 0.56 | X19: 0.57 | Y19: 0.51 | Z19: 106.5738 | AA19: 104.1936 | AB19: 103.1593 | AC19: 383682.64 | AD19: 1962460.5 | AE19: 5786.3702 | AF19: 25103.11 | AG19: 66308 | AH19: 78176 | AI19: 143.695 | AJ19: 134.6162 | AK19: 0.536 | AL19: 0.308 | AM19: 0.759 | AN19: 0.657 | AO19: 0.675 | AP19: 0.527 | AQ19: 0.809 | AR19: 0.72 | AS19: 0.761 | AT19: 0.712 | AU19: 0.841 | AV19: 0.737 | AW19: 86366 | AX19: 273498 | AY19: 1124534 | AZ19: 250722 | BA19: =AW19/SUM($AW19:$AZ19) -> 0.049775232 | BB19: =AX19/SUM($AW19:$AZ19) -> 0.15762483 | BC19: =AY19/SUM($AW19:$AZ19) -> 0.64810157 | BD19: =AZ19/SUM($AW19:$AZ19) -> 0.14449836 | BG19: =(Q19/Q$2-1)^2 -> 0.12999295 | BH19: =(R19/R$2-1)^2 -> 0.74917026 | BI19: =(S19/S$2-1)^2 -> 0.27894981 | BJ19: =(T19/T$2-1)^2 -> 0.66760262 | BK19: =(U19/U$2-1)^2 -> 0.12818992 | BL19: =(V19/V$2-1)^2 -> 0.74916929 | BM19: =(W19/W$2-1)^2 -> 0.0044444444 | BN19: =(X19/X$2-1)^2 -> 0 | ... CT19: =(BD19/BD$2-1)^2 -> 6.1395301 | CV19: =D19 -> Alfenas | CW19: =INDEX($BG$4:$CT$855,MATCH($CV19,$D$4:$D$855,0),MATCH(CW$1,$BG$1:$CT$1,0)) -> 0.74917026 | CX19: =INDEX($BG$4:$CT$855,MATCH($CV19,$D$4:$D$855,0),MATCH(CX$1,$BG$1:$CT$1,0)) -> 0.27894981 | CY19: =INDEX($BG$4:$CT$855,MATCH($CV19,$D$4:$D$855,0),MATCH(CY$1,$BG$1:$CT$1,0)) -> 0 | CZ19: =INDEX($BG$4:$CT$855,MATCH($CV19,$D$4:$D$855,0),MATCH(CZ$1,$BG$1:$CT$1,0)) -> 0.50161522 | DA19: =INDEX($BG$4:$CT$855,MATCH($CV19,$D$4:$D$855,0),MATCH(DA$1,$BG$1:$CT$1,0)) -> 0.11728505 | DB19: =INDEX($BG$4:$CT$855,MATCH($CV19,$D$4:$D$855,0),MATCH(DB$1,$BG$1:$CT$1,0)) -> 0.00065569125 | DC19: =INDEX($BG$4:$CT$855,MATCH($CV19,$D$4:$D$855,0),MATCH(DC$1,$BG$1:$CT$1,0)) -> 0.0052257222 | DD19: =INDEX($BG$4:$CT$855,MATCH($CV19,$D$4:$D$855,0),MATCH(DD$1,$BG$1:$CT$1,0)) -> 0.0014256241 | ... DI19: =INDEX($BG$4:$CT$855,MATCH($CV19,$D$4:$D$855,0),MATCH(DI$1,$BG$1:$CT$1,0)) -> 6.1395301 | DJ19: =AVERAGE(CW19:DI19) -> 7.7664527 | DL19: =DL18+1 -> 16 | DM19: =SMALL($DJ$4:$DJ$855,DL19) -> 0.58182937 | DN19: =INDEX($CV$4:$DJ$855,MATCH($DM19,$DJ$4:$DJ$855,0),1) -> João Monlevade
A20: 310163 | B20: Sudeste | C20: MG | D20: Alfredo Vasconcelos | E20: 4306 | F20: 26.32 | G20: 65.34 | H20: 1133.3392 | I20: 2813.5404 | J20: 84.8448 | K20: 5101 | L20: 14.84 | M20: 36.69 | N20: 756.9884 | O20: 1871.5569 | P20: 71.7232 | Q20: 6075 | R20: 3.52 | S20: 16.92 | T20: 213.84 | U20: 1027.89 | V20: 31.0367 | W20: 0.52 | X20: 0.52 | Y20: 0.41 | Z20: 98.9614 | AA20: 95.0538 | AB20: 82.932 | AC20: 15762.793 | AD20: 73000.138 | AE20: 3098.0332 | AF20: 11117.9 | AG20: 5088 | AH20: 6566 | AI20: 76.9346 | AJ20: 59.6201 | AK20: 0.405 | AL20: 0.192 | AM20: 0.689 | AN20: 0.503 | AO20: 0.573 | AP20: 0.433 | AQ20: 0.758 | AR20: 0.572 | AS20: 0.675 | AT20: 0.587 | AU20: 0.834 | AV20: 0.629 | AW20: 23490 | AX20: 9824 | AY20: 16593 | AZ20: 20883 | BA20: =AW20/SUM($AW20:$AZ20) -> 0.33182653 | BB20: =AX20/SUM($AW20:$AZ20) -> 0.13877666 | BC20: =AY20/SUM($AW20:$AZ20) -> 0.23439751 | BD20: =AZ20/SUM($AW20:$AZ20) -> 0.29499929 | BG20: =(Q20/Q$2-1)^2 -> 0.78732292 | BH20: =(R20/R$2-1)^2 -> 0.00019615689 | BI20: =(S20/S$2-1)^2 -> 0.19685727 | BJ20: =(T20/T$2-1)^2 -> 0.79012623 | BK20: =(U20/U$2-1)^2 -> 0.70109504 | BL20: =(V20/V$2-1)^2 -> 0.00019619005 | BM20: =(W20/W$2-1)^2 -> 0.017777778 | BN20: =(X20/X$2-1)^2 -> 0.0076946753 | ... CT20: =(BD20/BD$2-1)^2 -> 37.211046 | CV20: =D20 -> Alfredo Vasconcelos | CW20: =INDEX($BG$4:$CT$855,MATCH($CV20,$D$4:$D$855,0),MATCH(CW$1,$BG$1:$CT$1,0)) -> 0.00019615689 | CX20: =INDEX($BG$4:$CT$855,MATCH($CV20,$D$4:$D$855,0),MATCH(CX$1,$BG$1:$CT$1,0)) -> 0.19685727 | CY20: =INDEX($BG$4:$CT$855,MATCH($CV20,$D$4:$D$855,0),MATCH(CY$1,$BG$1:$CT$1,0)) -> 0.038446751 | CZ20: =INDEX($BG$4:$CT$855,MATCH($CV20,$D$4:$D$855,0),MATCH(CZ$1,$BG$1:$CT$1,0)) -> 0.75826851 | DA20: =INDEX($BG$4:$CT$855,MATCH($CV20,$D$4:$D$855,0),MATCH(DA$1,$BG$1:$CT$1,0)) -> 0.78720558 | DB20: =INDEX($BG$4:$CT$855,MATCH($CV20,$D$4:$D$855,0),MATCH(DB$1,$BG$1:$CT$1,0)) -> 0.0081534572 | DC20: =INDEX($BG$4:$CT$855,MATCH($CV20,$D$4:$D$855,0),MATCH(DC$1,$BG$1:$CT$1,0)) -> 0.013447616 | DD20: =INDEX($BG$4:$CT$855,MATCH($CV20,$D$4:$D$855,0),MATCH(DD$1,$BG$1:$CT$1,0)) -> 0.0020945808 | ... DI20: =INDEX($BG$4:$CT$855,MATCH($CV20,$D$4:$D$855,0),MATCH(DI$1,$BG$1:$CT$1,0)) -> 37.211046 | DJ20: =AVERAGE(CW20:DI20) -> 368.40524 | DL20: =DL19+1 -> 17 | DM20: =SMALL($DJ$4:$DJ$855,DL20) -> 0.60226049 | DN20: =INDEX($CV$4:$DJ$855,MATCH($DM20,$DJ$4:$DJ$855,0),1) -> Sarzedo
A21: 310170 | B21: Sudeste | C21: MG | D21: Almenara | E21: 32808 | F21: 35.38 | G21: 67.09 | H21: 11607.47 | I21: 22010.887 | J21: 114.0505 | K21: 34651 | L21: 23.13 | M21: 55.09 | N21: 8014.7763 | O21: 19089.236 | P21: 111.7897 | Q21: 38452 | R21: 9.33 | S21: 25.31 | T21: 3587.5716 | U21: 9732.2012 | V21: 82.2649 | W21: 0.69 | X21: 0.67 | Y21: 0.53 | Z21: 131.3142 | AA21: 122.4732 | AB21: 107.2048 | AC21: 66750.954 | AD21: 420167.22 | AE21: 1890.5334 | AF21: 10240.99 | AG21: 35308 | AH21: 41028 | AI21: 46.9483 | AJ21: 54.9176 | AK21: 0.382 | AL21: 0.158 | AM21: 0.629 | AN21: 0.56 | AO21: 0.529 | AP21: 0.349 | AQ21: 0.711 | AR21: 0.598 | AS21: 0.642 | AT21: 0.518 | AU21: 0.803 | AV21: 0.636 | AW21: 17299 | AX21: 50154 | AY21: 202077 | AZ21: 128202 | BA21: =AW21/SUM($AW21:$AZ21) -> 0.043494112 | BB21: =AX21/SUM($AW21:$AZ21) -> 0.12609999 | BC21: =AY21/SUM($AW21:$AZ21) -> 0.50807328 | BD21: =AZ21/SUM($AW21:$AZ21) -> 0.32233263 | BG21: =(Q21/Q$2-1)^2 -> 0.082218196 | BH21: =(R21/R$2-1)^2 -> 2.603206 | BI21: =(S21/S$2-1)^2 -> 1.3445708 | BJ21: =(T21/T$2-1)^2 -> 0.74662299 | BK21: =(U21/U$2-1)^2 -> 0.29195789 | BL21: =(V21/V$2-1)^2 -> 2.6031969 | BM21: =(W21/W$2-1)^2 -> 0.0225 | BN21: =(X21/X$2-1)^2 -> 0.030778701 | ... CT21: =(BD21/BD$2-1)^2 -> 45.669865 | CV21: =D21 -> Almenara | CW21: =INDEX($BG$4:$CT$855,MATCH($CV21,$D$4:$D$855,0),MATCH(CW$1,$BG$1:$CT$1,0)) -> 2.603206 | CX21: =INDEX($BG$4:$CT$855,MATCH($CV21,$D$4:$D$855,0),MATCH(CX$1,$BG$1:$CT$1,0)) -> 1.3445708 | CY21: =INDEX($BG$4:$CT$855,MATCH($CV21,$D$4:$D$855,0),MATCH(CY$1,$BG$1:$CT$1,0)) -> 0.00153787 | CZ21: =INDEX($BG$4:$CT$855,MATCH($CV21,$D$4:$D$855,0),MATCH(CZ$1,$BG$1:$CT$1,0)) -> 0.77612174 | DA21: =INDEX($BG$4:$CT$855,MATCH($CV21,$D$4:$D$855,0),MATCH(DA$1,$BG$1:$CT$1,0)) -> 0.087291313 | DB21: =INDEX($BG$4:$CT$855,MATCH($CV21,$D$4:$D$855,0),MATCH(DB$1,$BG$1:$CT$1,0)) -> 0.018163193 | DC21: =INDEX($BG$4:$CT$855,MATCH($CV21,$D$4:$D$855,0),MATCH(DC$1,$BG$1:$CT$1,0)) -> 0.048347002 | DD21: =INDEX($BG$4:$CT$855,MATCH($CV21,$D$4:$D$855,0),MATCH(DD$1,$BG$1:$CT$1,0)) -> 0.0065992386 | ... DI21: =INDEX($BG$4:$CT$855,MATCH($CV21,$D$4:$D$855,0),MATCH(DI$1,$BG$1:$CT$1,0)) -> 45.669865 | DJ21: =AVERAGE(CW21:DI21) -> 9.1513431 | DL21: =DL20+1 -> 18 | DM21: =SMALL($DJ$4:$DJ$855,DL21) -> 0.61249401 | DN21: =INDEX($CV$4:$DJ$855,MATCH($DM21,$DJ$4:$DJ$855,0),1) -> Itaú de Minas
A22: 310180 | B22: Sudeste | C22: MG | D22: Alpercata | E22: 6645 | F22: 24.85 | G22: 64.85 | H22: 1651.2825 | I22: 4309.2825 | J22: 80.1061 | K22: 6819 | L22: 10.62 | M22: 36.74 | N22: 724.1778 | O22: 2505.3006 | P22: 51.3275 | Q22: 7123 | R22: 4.2 | S22: 15.19 | T22: 299.166 | U22: 1081.9837 | V22: 37.0324 | W22: 0.44 | X22: 0.52 | Y22: 0.45 | Z22: 83.7366 | AA22: 95.0538 | AB22: 91.0229 | AC22: 17449.664 | AD22: 63570.66 | AE22: 2508.5773 | AF22: 8523.82 | AG22: 6956 | AH22: 7458 | AI22: 62.2964 | AJ22: 45.7092 | AK22: 0.374 | AL22: 0.154 | AM22: 0.716 | AN22: 0.475 | AO22: 0.549 | AP22: 0.381 | AQ22: 0.747 | AR22: 0.58 | AS22: 0.646 | AT22: 0.521 | AU22: 0.824 | AV22: 0.629 | AW22: 6066 | AX22: 4046 | AY22: 23567 | AZ22: 26806 | BA22: =AW22/SUM($AW22:$AZ22) -> 0.10028933 | BB22: =AX22/SUM($AW22:$AZ22) -> 0.066892618 | BC22: =AY22/SUM($AW22:$AZ22) -> 0.38963379 | BD22: =AZ22/SUM($AW22:$AZ22) -> 0.44318426 | BG22: =(Q22/Q$2-1)^2 -> 0.75320247 | BH22: =(R22/R$2-1)^2 -> 0.031141869 | BI22: =(S22/S$2-1)^2 -> 0.087660456 | BJ22: =(T22/T$2-1)^2 -> 0.7132744 | BK22: =(U22/U$2-1)^2 -> 0.68683101 | BL22: =(V22/V$2-1)^2 -> 0.031141077 | BM22: =(W22/W$2-1)^2 -> 0.071111111 | BN22: =(X22/X$2-1)^2 -> 0.0076946753 | ... CT22: =(BD22/BD$2-1)^2 -> 93.443599 | CV22: =D22 -> Alpercata | CW22: =INDEX($BG$4:$CT$855,MATCH($CV22,$D$4:$D$855,0),MATCH(CW$1,$BG$1:$CT$1,0)) -> 0.031141869 | CX22: =INDEX($BG$4:$CT$855,MATCH($CV22,$D$4:$D$855,0),MATCH(CX$1,$BG$1:$CT$1,0)) -> 0.087660456 | CY22: =INDEX($BG$4:$CT$855,MATCH($CV22,$D$4:$D$855,0),MATCH(CY$1,$BG$1:$CT$1,0)) -> 0.01384083 | CZ22: =INDEX($BG$4:$CT$855,MATCH($CV22,$D$4:$D$855,0),MATCH(CZ$1,$BG$1:$CT$1,0)) -> 0.81168373 | DA22: =INDEX($BG$4:$CT$855,MATCH($CV22,$D$4:$D$855,0),MATCH(DA$1,$BG$1:$CT$1,0)) -> 0.76025894 | DB22: =INDEX($BG$4:$CT$855,MATCH($CV22,$D$4:$D$855,0),MATCH(DB$1,$BG$1:$CT$1,0)) -> 0.016739198 | DC22: =INDEX($BG$4:$CT$855,MATCH($CV22,$D$4:$D$855,0),MATCH(DC$1,$BG$1:$CT$1,0)) -> 0.046380552 | DD22: =INDEX($BG$4:$CT$855,MATCH($CV22,$D$4:$D$855,0),MATCH(DD$1,$BG$1:$CT$1,0)) -> 0.0032727825 | ... DI22: =INDEX($BG$4:$CT$855,MATCH($CV22,$D$4:$D$855,0),MATCH(DI$1,$BG$1:$CT$1,0)) -> 93.443599 | DJ22: =AVERAGE(CW22:DI22) -> 38.587112 | DL22: =DL21+1 -> 19 | DM22: =SMALL($DJ$4:$DJ$855,DL22) -> 0.61926666 | DN22: =INDEX($CV$4:$DJ$855,MATCH($DM22,$DJ$4:$DJ$855,0),1) -> Itatiaiuçu
A23: 310190 | B23: Sudeste | C23: MG | D23: Alpinópolis | E23: 13832 | F23: 9 | G23: 40.35 | H23: 1244.88 | I23: 5581.212 | J23: 29.0123 | K23: 16932 | L23: 2.74 | M23: 12.44 | N23: 463.9368 | O23: 2106.3408 | P23: 13.2427 | Q23: 18351 | R23: 1.31 | S23: 8.46 | T23: 240.3981 | U23: 1552.4946 | V23: 11.5506 | W23: 0.56 | X23: 0.48 | Y23: 0.47 | Z23: 106.5738 | AA23: 87.742 | AB23: 95.0684 | AC23: 60285.215 | AD23: 288919.05 | AE23: 3561.0618 | AF23: 14806.49 | AG23: 16929 | AH23: 19513 | AI23: 88.4331 | AJ23: 79.4002 | AK23: 0.433 | AL23: 0.186 | AM23: 0.734 | AN23: 0.596 | AO23: 0.633 | AP23: 0.477 | AQ23: 0.81 | AR23: 0.655 | AS23: 0.725 | AT23: 0.629 | AU23: 0.862 | AV23: 0.703 | AW23: 49754 | AX23: 25054 | AY23: 130335 | AZ23: 61510 | BA23: =AW23/SUM($AW23:$AZ23) -> 0.18658706 | BB23: =AX23/SUM($AW23:$AZ23) -> 0.093957315 | BC23: =AY23/SUM($AW23:$AZ23) -> 0.4887813 | BD23: =AZ23/SUM($AW23:$AZ23) -> 0.23067432 | BG23: =(Q23/Q$2-1)^2 -> 0.43507128 | BH23: =(R23/R$2-1)^2 -> 0.40075638 | BI23: =(S23/S$2-1)^2 -> 0.077371315 | BJ23: =(T23/T$2-1)^2 -> 0.76578438 | BK23: =(U23/U$2-1)^2 -> 0.56894459 | BL23: =(V23/V$2-1)^2 -> 0.40075654 | BM23: =(W23/W$2-1)^2 -> 0.0044444444 | BN23: =(X23/X$2-1)^2 -> 0.024930748 | ... CT23: =(BD23/BD$2-1)^2 -> 20.719821 | CV23: =D23 -> Alpinópolis | CW23: =INDEX($BG$4:$CT$855,MATCH($CV23,$D$4:$D$855,0),MATCH(CW$1,$BG$1:$CT$1,0)) -> 0.40075638 | CX23: =INDEX($BG$4:$CT$855,MATCH($CV23,$D$4:$D$855,0),MATCH(CX$1,$BG$1:$CT$1,0)) -> 0.077371315 | CY23: =INDEX($BG$4:$CT$855,MATCH($CV23,$D$4:$D$855,0),MATCH(CY$1,$BG$1:$CT$1,0)) -> 0.0061514802 | CZ23: =INDEX($BG$4:$CT$855,MATCH($CV23,$D$4:$D$855,0),MATCH(CZ$1,$BG$1:$CT$1,0)) -> 0.68544625 | DA23: =INDEX($BG$4:$CT$855,MATCH($CV23,$D$4:$D$855,0),MATCH(DA$1,$BG$1:$CT$1,0)) -> 0.44211207 | DB23: =INDEX($BG$4:$CT$855,MATCH($CV23,$D$4:$D$855,0),MATCH(DB$1,$BG$1:$CT$1,0)) -> 0.00052491627 | DC23: =INDEX($BG$4:$CT$855,MATCH($CV23,$D$4:$D$855,0),MATCH(DC$1,$BG$1:$CT$1,0)) -> 0.002778433 | DD23: =INDEX($BG$4:$CT$855,MATCH($CV23,$D$4:$D$855,0),MATCH(DD$1,$BG$1:$CT$1,0)) -> 0.00018851227 | ... DI23: =INDEX($BG$4:$CT$855,MATCH($CV23,$D$4:$D$855,0),MATCH(DI$1,$BG$1:$CT$1,0)) -> 20.719821 | DJ23: =AVERAGE(CW23:DI23) -> 114.77073 | DL23: =DL22+1 -> 20 | DM23: =SMALL($DJ$4:$DJ$855,DL23) -> 0.6401738 | DN23: =INDEX($CV$4:$DJ$855,MATCH($DM23,$DJ$4:$DJ$855,0),1) -> Barão de Cocais
A24: 310200 | B24: Sudeste | C24: MG | D24: Alterosa | E24: 11563 | F24: 22.58 | G24: 50.72 | H24: 2610.9254 | I24: 5864.7536 | J24: 72.7886 | K24: 12926 | L24: 4.14 | M24: 20.56 | N24: 535.1364 | O24: 2657.5856 | P24: 20.009 | Q24: 13675 | R24: 3.97 | S24: 12.4 | T24: 542.8975 | U24: 1695.7 | V24: 35.0044 | W24: 0.49 | X24: 0.48 | Y24: 0.44 | Z24: 93.2521 | AA24: 87.742 | AB24: 89.0002 | AC24: 39268.221 | AD24: 168757.05 | AE24: 3040.7481 | AF24: 11742.89 | AG24: 12914 | AH24: 14371 | AI24: 75.512 | AJ24: 62.9716 | AK24: 0.37 | AL24: 0.137 | AM24: 0.71 | AN24: 0.521 | AO24: 0.565 | AP24: 0.386 | AQ24: 0.754 | AR24: 0.62 | AS24: 0.668 | AT24: 0.536 | AU24: 0.847 | AV24: 0.657 | AW24: 33899 | AX24: 11123 | AY24: 70109 | AZ24: 46156 | BA24: =AW24/SUM($AW24:$AZ24) -> 0.21017813 | BB24: =AX24/SUM($AW24:$AZ24) -> 0.068964021 | BC24: =AY24/SUM($AW24:$AZ24) -> 0.43468475 | BD24: =AZ24/SUM($AW24:$AZ24) -> 0.2861731 | BG24: =(Q24/Q$2-1)^2 -> 0.55701815 | BH24: =(R24/R$2-1)^2 -> 0.012554041 | BI24: =(S24/S$2-1)^2 -> 0.0033663758 | BJ24: =(T24/T$2-1)^2 -> 0.51540167 | BK24: =(U24/U$2-1)^2 -> 0.53526608 | BL24: =(V24/V$2-1)^2 -> 0.012553315 | BM24: =(W24/W$2-1)^2 -> 0.033611111 | BN24: =(X24/X$2-1)^2 -> 0.024930748 | ... CT24: =(BD24/BD$2-1)^2 -> 34.664487 | CV24: =D24 -> Alterosa | CW24: =INDEX($BG$4:$CT$855,MATCH($CV24,$D$4:$D$855,0),MATCH(CW$1,$BG$1:$CT$1,0)) -> 0.012554041 | CX24: =INDEX($BG$4:$CT$855,MATCH($CV24,$D$4:$D$855,0),MATCH(CX$1,$BG$1:$CT$1,0)) -> 0.0033663758 | CY24: =INDEX($BG$4:$CT$855,MATCH($CV24,$D$4:$D$855,0),MATCH(CY$1,$BG$1:$CT$1,0)) -> 0.018838908 | CZ24: =INDEX($BG$4:$CT$855,MATCH($CV24,$D$4:$D$855,0),MATCH(CZ$1,$BG$1:$CT$1,0)) -> 0.74567097 | DA24: =INDEX($BG$4:$CT$855,MATCH($CV24,$D$4:$D$855,0),MATCH(DA$1,$BG$1:$CT$1,0)) -> 0.56733364 | DB24: =INDEX($BG$4:$CT$855,MATCH($CV24,$D$4:$D$855,0),MATCH(DB$1,$BG$1:$CT$1,0)) -> 0.0099461643 | DC24: =INDEX($BG$4:$CT$855,MATCH($CV24,$D$4:$D$855,0),MATCH(DC$1,$BG$1:$CT$1,0)) -> 0.037160691 | DD24: =INDEX($BG$4:$CT$855,MATCH($CV24,$D$4:$D$855,0),MATCH(DD$1,$BG$1:$CT$1,0)) -> 0.00095434338 | ... DI24: =INDEX($BG$4:$CT$855,MATCH($CV24,$D$4:$D$855,0),MATCH(DI$1,$BG$1:$CT$1,0)) -> 34.664487 | DJ24: =AVERAGE(CW24:DI24) -> 147.0044 | DL24: =DL23+1 -> 21 | DM24: =SMALL($DJ$4:$DJ$855,DL24) -> 0.75617303 | DN24: =INDEX($CV$4:$DJ$855,MATCH($DM24,$DJ$4:$DJ$855,0),1) -> Confins
A25: 310205 | B25: Sudeste | C25: MG | D25: Alto Caparaó | E25: 3350 | F25: 15.02 | G25: 42.88 | H25: 503.17 | I25: 1436.48 | J25: 48.4183 | K25: 4583 | L25: 2.06 | M25: 21.56 | N25: 94.4098 | O25: 988.0948 | P25: 9.9562 | Q25: 5238 | R25: 2.81 | S25: 11.78 | T25: 147.1878 | U25: 617.0364 | V25: 24.7764 | W25: 0.51 | X25: 0.61 | Y25: 0.45 | Z25: 97.0583 | AA25: 111.5055 | AB25: 91.0229 | AC25: 24362.512 | AD25: 56355.195 | AE25: 5265.2933 | AF25: 9965.55 | AG25: 4627 | AH25: 5655 | AI25: 130.7549 | AJ25: 53.4406 | AK25: 0.398 | AL25: 0.162 | AM25: 0.697 | AN25: 0.559 | AO25: 0.57 | AP25: 0.343 | AQ25: 0.784 | AR25: 0.69 | AS25: 0.661 | AT25: 0.514 | AU25: 0.842 | AV25: 0.666 | AW25: 10914 | AX25: 2737 | AY25: 20375 | AZ25: 20398 | BA25: =AW25/SUM($AW25:$AZ25) -> 0.20053653 | BB25: =AX25/SUM($AW25:$AZ25) -> 0.050290313 | BC25: =AY25/SUM($AW25:$AZ25) -> 0.37437528 | BD25: =AZ25/SUM($AW25:$AZ25) -> 0.37479788 | BG25: =(Q25/Q$2-1)^2 -> 0.81511657 | BH25: =(R25/R$2-1)^2 -> 0.045320089 | BI25: =(S25/S$2-1)^2 -> 2.6208808e-05 | BJ25: =(T25/T$2-1)^2 -> 0.85289362 | BK25: =(U25/U$2-1)^2 -> 0.81421864 | BL25: =(V25/V$2-1)^2 -> 0.045321256 | BM25: =(W25/W$2-1)^2 -> 0.0225 | BN25: =(X25/X$2-1)^2 -> 0.0049245922 | ... CT25: =(BD25/BD$2-1)^2 -> 64.331463 | CV25: =D25 -> Alto Caparaó | CW25: =INDEX($BG$4:$CT$855,MATCH($CV25,$D$4:$D$855,0),MATCH(CW$1,$BG$1:$CT$1,0)) -> 0.045320089 | CX25: =INDEX($BG$4:$CT$855,MATCH($CV25,$D$4:$D$855,0),MATCH(CX$1,$BG$1:$CT$1,0)) -> 2.6208808e-05 | CY25: =INDEX($BG$4:$CT$855,MATCH($CV25,$D$4:$D$855,0),MATCH(CY$1,$BG$1:$CT$1,0)) -> 0.01384083 | CZ25: =INDEX($BG$4:$CT$855,MATCH($CV25,$D$4:$D$855,0),MATCH(CZ$1,$BG$1:$CT$1,0)) -> 0.78177237 | DA25: =INDEX($BG$4:$CT$855,MATCH($CV25,$D$4:$D$855,0),MATCH(DA$1,$BG$1:$CT$1,0)) -> 0.81521056 | DB25: =INDEX($BG$4:$CT$855,MATCH($CV25,$D$4:$D$855,0),MATCH(DB$1,$BG$1:$CT$1,0)) -> 0.011916871 | DC25: =INDEX($BG$4:$CT$855,MATCH($CV25,$D$4:$D$855,0),MATCH(DC$1,$BG$1:$CT$1,0)) -> 0.051032443 | DD25: =INDEX($BG$4:$CT$855,MATCH($CV25,$D$4:$D$855,0),MATCH(DD$1,$BG$1:$CT$1,0)) -> 0.0013405317 | ... DI25: =INDEX($BG$4:$CT$855,MATCH($CV25,$D$4:$D$855,0),MATCH(DI$1,$BG$1:$CT$1,0)) -> 64.331463 | DJ25: =AVERAGE(CW25:DI25) -> 136.08093 | DL25: =DL24+1 -> 22 | DM25: =SMALL($DJ$4:$DJ$855,DL25) -> 0.7923294 | DN25: =INDEX($CV$4:$DJ$855,MATCH($DM25,$DJ$4:$DJ$855,0),1) -> Ubá
